<mujoco model="apartment">
  <compiler angle="radian" meshdir="apartment/meshes/" texturedir="apartment/textures/"/>

  <default>
    <default class="apartment_visual">
      <geom contype="0" conaffinity="0" group="2"/>
    </default>
    <default class="apartment_collision">
      <geom group="3" rgba="0.9 0.9 0.9 1"/>
    </default>
    <default class="apartment">
      <joint stiffness="100" damping="1000"/>
    </default>
  </default>

  <asset>
    <texture type="2d" colorspace="linear" name="SM_Kitchen_03_Fridge" file="SM_Kitchen_03_Fridge.png"/>
    <texture type="2d" colorspace="linear" name="SM_Fridge_Base" file="SM_Fridge_Base.png"/>
    <texture type="2d" colorspace="linear" name="SM_Kitchen_04_Base" file="SM_Kitchen_04_Base.png"/>
    <texture type="2d" colorspace="linear" name="SM_Kitchen_04_Door_01" file="SM_Kitchen_04_Door_01.png"/>
    <texture type="2d" colorspace="linear" name="SM_Kitchen_04_Door_02" file="SM_Kitchen_04_Door_02.png"/>
    <texture type="2d" colorspace="linear" name="SM_Kitchen_06_Base" file="SM_Kitchen_06_Base.png"/>
    <texture type="2d" colorspace="linear" name="SM_Kitchen_Island_Cover_04" file="SM_Kitchen_Island_Cover_04.png"/>
    <texture type="2d" colorspace="linear" name="SM_Kitchen_05_Base" file="SM_Kitchen_05_Base.png"/>
    <texture type="2d" colorspace="linear" name="SM_Kitchen_Base_Board_01" file="SM_Kitchen_Base_Board_01.png"/>
    <texture type="2d" colorspace="linear" name="SM_Kitchen_02_Base" file="SM_Kitchen_02_Base.png"/>
    <texture type="2d" colorspace="linear" name="SM_Kitchen_02_Shelf" file="SM_Kitchen_02_Shelf.png"/>
    <texture type="2d" colorspace="linear" name="SM_Kitchen_01_Base" file="SM_Kitchen_01_Base.png"/>
    <texture type="2d" colorspace="linear" name="SM_Oven" file="SM_Oven.png"/>
    <texture type="2d" colorspace="linear" name="SM_Counter_Wall" file="SM_Counter_Wall.png"/>
    <texture type="2d" colorspace="linear" name="SM_Kitchen_08_Sink_Base" file="SM_Kitchen_08_Sink_Base.png"/>
    <texture type="2d" colorspace="linear" name="SM_Kitchen_10_Base" file="SM_Kitchen_10_Base.png"/>
    <texture type="2d" colorspace="linear" name="SM_Kitchen_11_Base" file="SM_Kitchen_11_Base.png"/>
    <texture type="2d" colorspace="linear" name="SM_Kitchen_Base_Board_02" file="SM_Kitchen_Base_Board_02.png"/>
    <texture type="2d" colorspace="linear" name="SM_Counter_Sink_Stove" file="SM_Counter_Sink_Stove.png"/>
    <texture type="2d" colorspace="linear" name="SM_Stove" file="SM_Stove.png"/>
    <texture type="2d" colorspace="linear" name="SM_Counter_Sink" file="SM_Counter_Sink.png"/>
    <texture type="2d" colorspace="linear" name="SM_Counter_Watertab" file="SM_Counter_Watertab.png"/>
    <texture type="2d" colorspace="linear" name="SM_Kitchen_Island_Cover_01" file="SM_Kitchen_Island_Cover_01.png"/>
    <texture type="2d" colorspace="linear" name="SM_Dishwasher_Base" file="SM_Dishwasher_Base.png"/>
    <texture type="2d" colorspace="linear" name="SM_Kitchen_09_Base" file="SM_Kitchen_09_Base.png"/>
    <texture type="2d" colorspace="linear" name="SM_Fridge_Door_01" file="SM_Fridge_Door_01.png"/>
    <texture type="2d" colorspace="linear" name="SM_Fridge_Door_Tray_01" file="SM_Fridge_Door_Tray_01.png"/>
    <texture type="2d" colorspace="linear" name="SM_Fridge_Door_Tray_02" file="SM_Fridge_Door_Tray_02.png"/>
    <texture type="2d" colorspace="linear" name="SM_Fridge_Egg_Tray" file="SM_Fridge_Egg_Tray.png"/>
    <texture type="2d" colorspace="linear" name="SM_Fridge_Door_02" file="SM_Fridge_Door_02.png"/>
    <texture type="2d" colorspace="linear" name="SM_Fridge_Drawer_01" file="SM_Fridge_Drawer_01.png"/>
    <texture type="2d" colorspace="linear" name="SM_Fridge_Drawer_03" file="SM_Fridge_Drawer_03.png"/>
    <texture type="2d" colorspace="linear" name="SM_Fridge_Drawer_05" file="SM_Fridge_Drawer_05.png"/>
    <texture type="2d" colorspace="linear" name="SM_Fridge_Drawer_04" file="SM_Fridge_Drawer_04.png"/>
    <texture type="2d" colorspace="linear" name="SM_Fridge_Drawer_02" file="SM_Fridge_Drawer_02.png"/>
    <texture type="2d" colorspace="linear" name="SM_Kitchen_06_Drawer_02" file="SM_Kitchen_06_Drawer_02.png"/>
    <texture type="2d" colorspace="linear" name="SM_Kitchen_06_Drawer_03" file="SM_Kitchen_06_Drawer_03.png"/>
    <texture type="2d" colorspace="linear" name="SM_Kitchen_06_Drawer_01" file="SM_Kitchen_06_Drawer_01.png"/>
    <texture type="2d" colorspace="linear" name="SM_Kitchen_05_Drawer_02" file="SM_Kitchen_05_Drawer_02.png"/>
    <texture type="2d" colorspace="linear" name="SM_Kitchen_05_Drawer_03" file="SM_Kitchen_05_Drawer_03.png"/>
    <texture type="2d" colorspace="linear" name="SM_Kitchen_05_Drawer_01" file="SM_Kitchen_05_Drawer_01.png"/>
    <texture type="2d" colorspace="linear" name="SM_Kitchen_02_Door" file="SM_Kitchen_02_Door.png"/>
    <texture type="2d" colorspace="linear" name="SM_Kitchen_02_Drawer_01" file="SM_Kitchen_02_Drawer_01.png"/>
    <texture type="2d" colorspace="linear" name="SM_Oven_Door" file="SM_Oven_Door.png"/>
    <texture type="2d" colorspace="linear" name="SM_Kitchen_01_Door_01" file="SM_Kitchen_01_Door_01.png"/>
    <texture type="2d" colorspace="linear" name="SM_Kitchen_01_Drawer_01" file="SM_Kitchen_01_Drawer_01.png"/>
    <texture type="2d" colorspace="linear" name="SM_Kitchen_01_Drawer_02" file="SM_Kitchen_01_Drawer_02.png"/>
    <texture type="2d" colorspace="linear" name="SM_Kitchen_08_Sink_Drawer_02" file="SM_Kitchen_08_Sink_Drawer_02.png"/>
    <texture type="2d" colorspace="linear" name="SM_Kitchen_08_Sink_Drawer_01" file="SM_Kitchen_08_Sink_Drawer_01.png"/>
    <texture type="2d" colorspace="linear" name="SM_Kitchen_10_Drawer_02" file="SM_Kitchen_10_Drawer_02.png"/>
    <texture type="2d" colorspace="linear" name="SM_Kitchen_10_Drawer_03" file="SM_Kitchen_10_Drawer_03.png"/>
    <texture type="2d" colorspace="linear" name="SM_Kitchen_10_Drawer_01" file="SM_Kitchen_10_Drawer_01.png"/>
    <texture type="2d" colorspace="linear" name="SM_Kitchen_11_Drawer_02" file="SM_Kitchen_11_Drawer_02.png"/>
    <texture type="2d" colorspace="linear" name="SM_Kitchen_11_Drawer_03" file="SM_Kitchen_11_Drawer_03.png"/>
    <texture type="2d" colorspace="linear" name="SM_Kitchen_11_Drawer_01" file="SM_Kitchen_11_Drawer_01.png"/>
    <texture type="2d" colorspace="linear" name="SM_Counter_Sink_Tap" file="SM_Counter_Sink_Tap.png"/>
    <texture type="2d" colorspace="linear" name="SM_Dishwasher_Tray_01" file="SM_Dishwasher_Tray_01.png"/>
    <texture type="2d" colorspace="linear" name="SM_Dishwasher_Tray_03" file="SM_Dishwasher_Tray_03.png"/>
    <texture type="2d" colorspace="linear" name="SM_Dishwasher_Tray_02" file="SM_Dishwasher_Tray_02.png"/>
    <texture type="2d" colorspace="linear" name="SM_Dishwasher_Front" file="SM_Dishwasher_Front.png"/>
    <texture type="2d" colorspace="linear" name="SM_Kitchen_09_Drawer_02" file="SM_Kitchen_09_Drawer_02.png"/>
    <texture type="2d" colorspace="linear" name="SM_Kitchen_09_Drawer_03" file="SM_Kitchen_09_Drawer_03.png"/>
    <texture type="2d" colorspace="linear" name="SM_Kitchen_09_Drawer_01" file="SM_Kitchen_09_Drawer_01.png"/>
    <material name="SM_Kitchen_03_Fridge" texture="SM_Kitchen_03_Fridge"/>
    <material name="SM_Fridge_Base" texture="SM_Fridge_Base"/>
    <material name="SM_Fridge_Shelf"/>
    <material name="SM_Kitchen_04_Base" texture="SM_Kitchen_04_Base"/>
    <material name="SM_Kitchen_04_Door_01" texture="SM_Kitchen_04_Door_01"/>
    <material name="SM_Kitchen_04_Door_02" texture="SM_Kitchen_04_Door_02"/>
    <material name="SM_Kitchen_06_Base" texture="SM_Kitchen_06_Base"/>
    <material name="SM_Kitchen_Island_Cover_04" texture="SM_Kitchen_Island_Cover_04"/>
    <material name="SM_Kitchen_05_Base" texture="SM_Kitchen_05_Base"/>
    <material name="SM_Kitchen_Base_Board_01" texture="SM_Kitchen_Base_Board_01"/>
    <material name="SM_Kitchen_02_Base" texture="SM_Kitchen_02_Base"/>
    <material name="SM_Kitchen_02_Shelf" texture="SM_Kitchen_02_Shelf"/>
    <material name="SM_Kitchen_01_Base" texture="SM_Kitchen_01_Base"/>
    <material name="SM_Oven" texture="SM_Oven"/>
    <material name="SM_Counter_Wall" texture="SM_Counter_Wall"/>
    <material name="SM_Kitchen_08_Sink_Base" texture="SM_Kitchen_08_Sink_Base"/>
    <material name="SM_Kitchen_10_Base" texture="SM_Kitchen_10_Base"/>
    <material name="SM_Kitchen_11_Base" texture="SM_Kitchen_11_Base"/>
    <material name="SM_Kitchen_Base_Board_02" texture="SM_Kitchen_Base_Board_02"/>
    <material name="SM_Counter_Sink_Stove" texture="SM_Counter_Sink_Stove"/>
    <material name="SM_Stove" texture="SM_Stove"/>
    <material name="SM_Counter_Sink" texture="SM_Counter_Sink"/>
    <material name="SM_Counter_Watertab" texture="SM_Counter_Watertab"/>
    <material name="SM_Kitchen_Island_Cover_01" texture="SM_Kitchen_Island_Cover_01"/>
    <material name="SM_Dishwasher_Base" texture="SM_Dishwasher_Base"/>
    <material name="SM_Kitchen_09_Base" texture="SM_Kitchen_09_Base"/>
    <material name="SM_Kitchen_Island_Cover_03"/>
    <material name="SM_Fridge_Door_01" texture="SM_Fridge_Door_01"/>
    <material name="SM_Fridge_Door_Tray_01" texture="SM_Fridge_Door_Tray_01"/>
    <material name="SM_Fridge_Door_Tray_02" texture="SM_Fridge_Door_Tray_02"/>
    <material name="SM_Fridge_Egg_Tray" texture="SM_Fridge_Egg_Tray"/>
    <material name="SM_Fridge_Door_02" texture="SM_Fridge_Door_02"/>
    <material name="SM_Fridge_Drawer_01" texture="SM_Fridge_Drawer_01"/>
    <material name="SM_Fridge_Drawer_03" texture="SM_Fridge_Drawer_03"/>
    <material name="SM_Fridge_Drawer_05" texture="SM_Fridge_Drawer_05"/>
    <material name="SM_Fridge_Drawer_04" texture="SM_Fridge_Drawer_04"/>
    <material name="SM_Fridge_Drawer_02" texture="SM_Fridge_Drawer_02"/>
    <material name="SM_Kitchen_06_Drawer_02" texture="SM_Kitchen_06_Drawer_02"/>
    <material name="SM_Kitchen_06_Drawer_03" texture="SM_Kitchen_06_Drawer_03"/>
    <material name="SM_Kitchen_06_Drawer_01" texture="SM_Kitchen_06_Drawer_01"/>
    <material name="SM_Kitchen_05_Drawer_02" texture="SM_Kitchen_05_Drawer_02"/>
    <material name="SM_Kitchen_05_Drawer_03" texture="SM_Kitchen_05_Drawer_03"/>
    <material name="SM_Kitchen_05_Drawer_01" texture="SM_Kitchen_05_Drawer_01"/>
    <material name="SM_Kitchen_02_Door" texture="SM_Kitchen_02_Door"/>
    <material name="SM_Kitchen_02_Drawer_01" texture="SM_Kitchen_02_Drawer_01"/>
    <material name="SM_Kitchen_02_Drawer_02"/>
    <material name="SM_Oven_Door" texture="SM_Oven_Door"/>
    <material name="SM_Kitchen_01_Door_01" texture="SM_Kitchen_01_Door_01"/>
    <material name="SM_Kitchen_01_Drawer_01" texture="SM_Kitchen_01_Drawer_01"/>
    <material name="SM_Kitchen_01_Drawer_02" texture="SM_Kitchen_01_Drawer_02"/>
    <material name="SM_Kitchen_08_Sink_Drawer_02" texture="SM_Kitchen_08_Sink_Drawer_02"/>
    <material name="SM_Kitchen_08_Sink_Drawer_01" texture="SM_Kitchen_08_Sink_Drawer_01"/>
    <material name="SM_Kitchen_10_Drawer_02" texture="SM_Kitchen_10_Drawer_02"/>
    <material name="SM_Kitchen_10_Drawer_03" texture="SM_Kitchen_10_Drawer_03"/>
    <material name="SM_Kitchen_10_Drawer_01" texture="SM_Kitchen_10_Drawer_01"/>
    <material name="SM_Kitchen_11_Drawer_02" texture="SM_Kitchen_11_Drawer_02"/>
    <material name="SM_Kitchen_11_Drawer_03" texture="SM_Kitchen_11_Drawer_03"/>
    <material name="SM_Kitchen_11_Drawer_01" texture="SM_Kitchen_11_Drawer_01"/>
    <material name="SM_Counter_Sink_Tap" texture="SM_Counter_Sink_Tap"/>
    <material name="SM_Dishwasher_Tray_01" texture="SM_Dishwasher_Tray_01"/>
    <material name="SM_Dishwasher_Tray_03" texture="SM_Dishwasher_Tray_03"/>
    <material name="SM_Dishwasher_Tray_02" texture="SM_Dishwasher_Tray_02"/>
    <material name="SM_Dishwasher_Front" texture="SM_Dishwasher_Front"/>
    <material name="SM_Kitchen_09_Drawer_02" texture="SM_Kitchen_09_Drawer_02"/>
    <material name="SM_Kitchen_09_Drawer_03" texture="SM_Kitchen_09_Drawer_03"/>
    <material name="SM_Kitchen_09_Drawer_01" texture="SM_Kitchen_09_Drawer_01"/>
    <mesh name="SM_Kitchen_03_Fridge" content_type="model/obj" file="obj/SM_Kitchen_03_Fridge.obj"/>
    <mesh name="SM_Fridge_Door_01" content_type="model/obj" file="obj/SM_Fridge_Door_01.obj"/>
    <mesh name="SM_Kitchen_Handle" content_type="model/stl" file="stl/SM_Kitchen_Handle.stl"/>
    <mesh name="SM_Fridge_Door_Tray_01" content_type="model/obj" file="obj/SM_Fridge_Door_Tray_01.obj"/>
    <mesh name="SM_Fridge_Door_Tray_02" content_type="model/obj" file="obj/SM_Fridge_Door_Tray_02.obj"/>
    <mesh name="SM_Fridge_Egg_Tray" content_type="model/obj" file="obj/SM_Fridge_Egg_Tray.obj"/>
    <mesh name="SM_Fridge_Door_02" content_type="model/obj" file="obj/SM_Fridge_Door_02.obj"/>
    <mesh name="SM_Fridge_Base" content_type="model/obj" file="obj/SM_Fridge_Base.obj"/>
    <mesh name="SM_Fridge_Drawer_01" content_type="model/obj" file="obj/SM_Fridge_Drawer_01.obj"/>
    <mesh name="SM_Fridge_Drawer_03" content_type="model/obj" file="obj/SM_Fridge_Drawer_03.obj"/>
    <mesh name="SM_Fridge_Drawer_05" content_type="model/obj" file="obj/SM_Fridge_Drawer_05.obj"/>
    <mesh name="SM_Fridge_Shelf" content_type="model/stl" file="stl/SM_Fridge_Shelf.stl"/>
    <mesh name="SM_Fridge_Drawer_04" content_type="model/obj" file="obj/SM_Fridge_Drawer_04.obj"/>
    <mesh name="SM_Fridge_Drawer_02" content_type="model/obj" file="obj/SM_Fridge_Drawer_02.obj"/>
    <mesh name="SM_Kitchen_04_Base" content_type="model/obj" file="obj/SM_Kitchen_04_Base.obj"/>
    <mesh name="SM_Kitchen_04_Shelf" content_type="model/stl" file="stl/SM_Kitchen_04_Shelf.stl"/>
    <mesh name="SM_Kitchen_04_Door_01" content_type="model/obj" file="obj/SM_Kitchen_04_Door_01.obj"/>
    <mesh name="SM_Kitchen_04_Door_02" content_type="model/obj" file="obj/SM_Kitchen_04_Door_02.obj"/>
    <mesh name="SM_Kitchen_06_Base" content_type="model/obj" file="obj/SM_Kitchen_06_Base.obj"/>
    <mesh name="SM_Kitchen_06_Drawer_02" content_type="model/obj" file="obj/SM_Kitchen_06_Drawer_02.obj"/>
    <mesh name="SM_Kitchen_06_Drawer_03" content_type="model/obj" file="obj/SM_Kitchen_06_Drawer_03.obj"/>
    <mesh name="SM_Kitchen_06_Drawer_01" content_type="model/obj" file="obj/SM_Kitchen_06_Drawer_01.obj"/>
    <mesh name="SM_Kitchen_Island_Cover_04" content_type="model/obj" file="obj/SM_Kitchen_Island_Cover_04.obj"/>
    <mesh name="SM_Kitchen_05_Base" content_type="model/obj" file="obj/SM_Kitchen_05_Base.obj"/>
    <mesh name="SM_Kitchen_05_Drawer_02" content_type="model/obj" file="obj/SM_Kitchen_05_Drawer_02.obj"/>
    <mesh name="SM_Kitchen_05_Drawer_03" content_type="model/obj" file="obj/SM_Kitchen_05_Drawer_03.obj"/>
    <mesh name="SM_Kitchen_05_Drawer_01" content_type="model/obj" file="obj/SM_Kitchen_05_Drawer_01.obj"/>
    <mesh name="SM_Kitchen_Base_Board_01" content_type="model/obj" file="obj/SM_Kitchen_Base_Board_01.obj"/>
    <mesh name="SM_Kitchen_02_Base" content_type="model/obj" file="obj/SM_Kitchen_02_Base.obj"/>
    <mesh name="SM_Kitchen_02_Door" content_type="model/obj" file="obj/SM_Kitchen_02_Door.obj"/>
    <mesh name="SM_Kitchen_02_Drawer_01" content_type="model/obj" file="obj/SM_Kitchen_02_Drawer_01.obj"/>
    <mesh name="SM_Kitchen_02_Drawer_02" content_type="model/stl" file="stl/SM_Kitchen_02_Drawer_02.stl"/>
    <mesh name="SM_Kitchen_02_Shelf" content_type="model/obj" file="obj/SM_Kitchen_02_Shelf.obj"/>
    <mesh name="SM_Kitchen_01_Base" content_type="model/obj" file="obj/SM_Kitchen_01_Base.obj"/>
    <mesh name="SM_Oven" content_type="model/obj" file="obj/SM_Oven.obj"/>
    <mesh name="SM_Oven_Door" content_type="model/obj" file="obj/SM_Oven_Door.obj"/>
    <mesh name="SM_Kitchen_01_Door_01" content_type="model/obj" file="obj/SM_Kitchen_01_Door_01.obj"/>
    <mesh name="SM_Kitchen_01_Drawer_01" content_type="model/obj" file="obj/SM_Kitchen_01_Drawer_01.obj"/>
    <mesh name="SM_Kitchen_01_Drawer_02" content_type="model/obj" file="obj/SM_Kitchen_01_Drawer_02.obj"/>
    <mesh name="SM_Counter_Wall" content_type="model/obj" file="obj/SM_Counter_Wall.obj"/>
    <mesh name="SM_Kitchen_08_Sink_Base" content_type="model/obj" file="obj/SM_Kitchen_08_Sink_Base.obj"/>
    <mesh name="SM_Kitchen_08_Sink_Drawer_02" content_type="model/obj" file="obj/SM_Kitchen_08_Sink_Drawer_02.obj"/>
    <mesh name="SM_Kitchen_08_Sink_Drawer_01" content_type="model/obj" file="obj/SM_Kitchen_08_Sink_Drawer_01.obj"/>
    <mesh name="SM_Kitchen_10_Base" content_type="model/obj" file="obj/SM_Kitchen_10_Base.obj"/>
    <mesh name="SM_Kitchen_10_Drawer_02" content_type="model/obj" file="obj/SM_Kitchen_10_Drawer_02.obj"/>
    <mesh name="SM_Kitchen_10_Drawer_03" content_type="model/obj" file="obj/SM_Kitchen_10_Drawer_03.obj"/>
    <mesh name="SM_Kitchen_10_Drawer_01" content_type="model/obj" file="obj/SM_Kitchen_10_Drawer_01.obj"/>
    <mesh name="SM_Kitchen_11_Base" content_type="model/obj" file="obj/SM_Kitchen_11_Base.obj"/>
    <mesh name="SM_Kitchen_11_Drawer_02" content_type="model/obj" file="obj/SM_Kitchen_11_Drawer_02.obj"/>
    <mesh name="SM_Kitchen_11_Drawer_03" content_type="model/obj" file="obj/SM_Kitchen_11_Drawer_03.obj"/>
    <mesh name="SM_Kitchen_11_Drawer_01" content_type="model/obj" file="obj/SM_Kitchen_11_Drawer_01.obj"/>
    <mesh name="SM_Kitchen_Base_Board_02" content_type="model/obj" file="obj/SM_Kitchen_Base_Board_02.obj"/>
    <mesh name="SM_Counter_Sink_Stove" content_type="model/obj" file="obj/SM_Counter_Sink_Stove.obj"/>
    <mesh name="SM_Stove" content_type="model/obj" file="obj/SM_Stove.obj"/>
    <mesh name="SM_Counter_Sink" content_type="model/obj" file="obj/SM_Counter_Sink.obj"/>
    <mesh name="SM_Counter_Watertab" content_type="model/obj" file="obj/SM_Counter_Watertab.obj"/>
    <mesh name="SM_Counter_Sink_Tap" content_type="model/obj" file="obj/SM_Counter_Sink_Tap.obj"/>
    <mesh name="SM_Kitchen_Island_Cover_01" content_type="model/obj" file="obj/SM_Kitchen_Island_Cover_01.obj"/>
    <mesh name="SM_Dishwasher_Base" content_type="model/obj" file="obj/SM_Dishwasher_Base.obj"/>
    <mesh name="SM_Dishwasher_Tray_01" content_type="model/obj" file="obj/SM_Dishwasher_Tray_01.obj"/>
    <mesh name="SM_Dishwasher_Tray_03" content_type="model/obj" file="obj/SM_Dishwasher_Tray_03.obj"/>
    <mesh name="SM_Dishwasher_Tray_02" content_type="model/obj" file="obj/SM_Dishwasher_Tray_02.obj"/>
    <mesh name="SM_Dishwasher_Front" content_type="model/obj" file="obj/SM_Dishwasher_Front.obj"/>
    <mesh name="SM_Kitchen_09_Base" content_type="model/obj" file="obj/SM_Kitchen_09_Base.obj"/>
    <mesh name="SM_Kitchen_09_Drawer_02" content_type="model/obj" file="obj/SM_Kitchen_09_Drawer_02.obj"/>
    <mesh name="SM_Kitchen_09_Drawer_03" content_type="model/obj" file="obj/SM_Kitchen_09_Drawer_03.obj"/>
    <mesh name="SM_Kitchen_09_Drawer_01" content_type="model/obj" file="obj/SM_Kitchen_09_Drawer_01.obj"/>
    <mesh name="SM_Kitchen_Island_Cover_03" content_type="model/stl" file="stl/SM_Kitchen_Island_Cover_03.stl"/>
  </asset>

  <worldbody>
    <body gravcomp="1" name="apartment_root" childclass="apartment">
      <body gravcomp="1" name="kitchen_root">
        <body gravcomp="1" name="kitchen2_root" pos="0.1 0 0">
          <body gravcomp="1" name="cabinet10" pos="2.49299 2.27192 0.501119">
            <inertial pos="0.0450371 0.000277177 -0.0594252" quat="0.703774 0.0467616 0.0460588 0.707385" mass="275.729" diaginertia="18.6947 17.9737 9.98513"/>
            <geom name="geom_0" class="apartment_visual" pos="0.0458732 0.000298986 -0.059823" quat="0.703696 0.048073 0.0473212 0.707291" type="mesh" material="SM_Kitchen_10_Base" mesh="SM_Kitchen_10_Base"/>
            <body gravcomp="1" name="cabinet10_drawer3" pos="-0.0504031 -0.00036921 -0.203967">
              <inertial pos="-0.0240704 -8.07589e-07 -0.078561" quat="5.04155e-06 0.786789 3.34045e-06 0.617222" mass="76.1255" diaginertia="2.93394 2.53493 1.23062"/>
              <joint name="cabinet10_drawer3_joint" pos="0 0 0" axis="-1 0 0" type="slide" limited="true" range="0 0.45" actuatorfrclimited="false"/>
              <geom name="geom_1" class="apartment_visual" pos="-0.0218304 -1.31845e-06 -0.0777047" quat="5.34113e-06 0.785522 3.22518e-06 0.618834" type="mesh" material="SM_Kitchen_10_Drawer_03" mesh="SM_Kitchen_10_Drawer_03"/>
              <geom name="geom_2" class="apartment_collision" size="0.008 0.2 0.2" pos="-0.234 0 0" type="box"/>
              <geom name="geom_3" class="apartment_collision" size="0.25 0.18 0.008" pos="0.025 0 -0.164" type="box"/>
              <geom name="geom_4" class="apartment_collision" size="0.25 0.008 0.08" pos="0.025 -0.17 -0.075" type="box"/>
              <geom name="geom_5" class="apartment_collision" size="0.25 0.008 0.08" pos="0.025 0.17 -0.075" type="box"/>
              <geom name="geom_6" class="apartment_collision" size="0.008 0.16 0.08" pos="0.26 0 -0.075" type="box"/>
              <body gravcomp="1" name="cabinet10_drawer3_handle" pos="-0.267122 -0.00402777 0.151166" quat="0.707107 0.707107 0 0">
                <inertial pos="0.00608124 7.62691e-06 0.000219453" quat="0.707535 -0.0001654 -4.86875e-05 0.706679" mass="0.101418" diaginertia="0.000334346 0.000326533 1.03303e-05"/>
                <geom name="geom_7" class="apartment_visual" pos="0.00753596 3.13834e-07 -1.61273e-05" quat="0.707258 0.000144565 8.61629e-05 0.706956" type="mesh" mesh="SM_Kitchen_Handle"/>
                <geom name="geom_8" class="apartment_collision" size="0.01 0.0065 0.0065" pos="0.0164985 0 0.08" type="box"/>
                <geom name="geom_9" class="apartment_collision" size="0.0065 0.0065 0.086516" type="box"/>
                <geom name="geom_10" class="apartment_collision" size="0.01 0.0065 0.0065" pos="0.0164985 0 -0.08" type="box"/>
              </body>
            </body>
            <body gravcomp="1" name="cabinet10_drawer1" pos="-0.0509572 0.00062459 0.325652">
              <inertial pos="0.00345742 -4.81613e-07 -0.0212922" quat="2.30621e-06 0.71773 -2.23742e-06 0.696321" mass="39.0767" diaginertia="1.42835 0.98064 0.497708"/>
              <joint name="cabinet10_drawer1_joint" pos="0 0 0" axis="-1 0 0" type="slide" limited="true" range="0 0.45" actuatorfrclimited="false"/>
              <geom name="geom_11" class="apartment_visual" pos="0.00458842 -5.53513e-07 -0.0202851" quat="4.37941e-06 0.717731 -4.24878e-06 0.696321" type="mesh" material="SM_Kitchen_10_Drawer_01" mesh="SM_Kitchen_10_Drawer_01"/>
              <geom name="geom_12" class="apartment_collision" size="0.008 0.2 0.065" pos="-0.234 0 0" type="box"/>
              <geom name="geom_13" class="apartment_collision" size="0.25 0.18 0.008" pos="0.025 0 -0.045" type="box"/>
              <geom name="geom_14" class="apartment_collision" size="0.25 0.008 0.034" pos="0.025 -0.17 -0.005" type="box"/>
              <geom name="geom_15" class="apartment_collision" size="0.25 0.008 0.034" pos="0.025 0.17 -0.005" type="box"/>
              <geom name="geom_16" class="apartment_collision" size="0.008 0.16 0.034" pos="0.26 0 -0.005" type="box"/>
              <body gravcomp="1" name="cabinet10_drawer1_handle" pos="-0.266623 -0.00124599 0.0172039" quat="0.707107 0.707107 0 0">
                <inertial pos="0.00608124 7.62691e-06 0.000219453" quat="0.707535 -0.0001654 -4.86875e-05 0.706679" mass="0.101418" diaginertia="0.000334346 0.000326533 1.03303e-05"/>
                <geom name="geom_17" class="apartment_visual" pos="0.00753596 3.13834e-07 -1.61273e-05" quat="0.707258 0.000144565 8.61629e-05 0.706956" type="mesh" mesh="SM_Kitchen_Handle"/>
                <geom name="geom_18" class="apartment_collision" size="0.01 0.0065 0.0065" pos="0.0164985 0 0.08" type="box"/>
                <geom name="geom_19" class="apartment_collision" size="0.0065 0.0065 0.086516" type="box"/>
                <geom name="geom_20" class="apartment_collision" size="0.01 0.0065 0.0065" pos="0.0164985 0 -0.08" type="box"/>
              </body>
            </body>
            <body gravcomp="1" name="cabinet10_drawer2" pos="-0.0507138 -6.861e-05 0.128052">
              <inertial pos="-0.00359727 -7.25506e-07 -0.0493716" quat="3.35264e-06 0.74018 -2.15234e-07 0.672408" mass="64.8515" diaginertia="2.43881 1.91489 0.915224"/>
              <joint name="cabinet10_drawer2_joint" pos="0 0 0" axis="-1 0 0" type="slide" limited="true" range="0 0.45" actuatorfrclimited="false"/>
              <geom name="geom_21" class="apartment_visual" pos="-0.00200047 -6.44688e-07 -0.0480222" quat="3.87893e-06 0.739724 -2.86765e-07 0.67291" type="mesh" material="SM_Kitchen_10_Drawer_02" mesh="SM_Kitchen_10_Drawer_02"/>
              <geom name="geom_22" class="apartment_collision" size="0.008 0.2 0.13" pos="-0.234 0 0" type="box"/>
              <geom name="geom_23" class="apartment_collision" size="0.25 0.18 0.008" pos="0.025 0 -0.12" type="box"/>
              <geom name="geom_24" class="apartment_collision" size="0.25 0.008 0.08" pos="0.025 -0.17 -0.03" type="box"/>
              <geom name="geom_25" class="apartment_collision" size="0.25 0.008 0.08" pos="0.025 0.17 -0.03" type="box"/>
              <geom name="geom_26" class="apartment_collision" size="0.008 0.16 0.082" pos="0.26 0 -0.03" type="box"/>
              <body gravcomp="1" name="cabinet10_drawer2_handle" pos="-0.266862 -0.00397854 0.0854179" quat="0.707107 0.707107 0 0">
                <inertial pos="0.00608124 7.62691e-06 0.000219453" quat="0.707535 -0.0001654 -4.86875e-05 0.706679" mass="0.101418" diaginertia="0.000334346 0.000326533 1.03303e-05"/>
                <geom name="geom_27" class="apartment_visual" pos="0.00753596 3.13834e-07 -1.61273e-05" quat="0.707258 0.000144565 8.61629e-05 0.706956" type="mesh" mesh="SM_Kitchen_Handle"/>
                <geom name="geom_28" class="apartment_collision" size="0.01 0.0065 0.0065" pos="0.0164985 0 0.08" type="box"/>
                <geom name="geom_29" class="apartment_collision" size="0.0065 0.0065 0.086516" type="box"/>
                <geom name="geom_30" class="apartment_collision" size="0.01 0.0065 0.0065" pos="0.0164985 0 -0.08" type="box"/>
              </body>
            </body>
          </body>
          <body gravcomp="1" name="cabinet11" pos="2.49294 1.62156 0.509844">
            <inertial pos="0.0536945 -0.0106176 -0.0658134" quat="0.710849 0.699218 0.0506341 -0.0567751" mass="588.304" diaginertia="78.9614 62.0174 39.104"/>
            <geom name="geom_31" class="apartment_visual" pos="0.0534928 2.11921e-05 -0.064537" quat="0.705214 0.705069 0.0526845 -0.0526791" type="mesh" material="SM_Kitchen_11_Base" mesh="SM_Kitchen_11_Base"/>
            <body gravcomp="1" name="cabinet11_drawer3" pos="-0.0507752 0.00146352 -0.213308">
              <inertial pos="-0.0203705 -3.2327e-07 -0.0804326" quat="0.556599 0.5566 -0.436116 0.436117" mass="174.23" diaginertia="15.5049 11.5914 5.80762"/>
              <joint name="cabinet11_drawer3_joint" pos="0 0 0" axis="-1 0 0" type="slide" limited="true" range="0 0.45" actuatorfrclimited="false"/>
              <geom name="geom_32" class="apartment_visual" pos="-0.0174187 -1.47359e-07 -0.0799873" quat="0.555437 0.555438 -0.437594 0.437595" type="mesh" material="SM_Kitchen_11_Drawer_03" mesh="SM_Kitchen_11_Drawer_03"/>
              <geom name="geom_33" class="apartment_collision" size="0.008 0.448 0.2" pos="-0.234 0 0" type="box"/>
              <geom name="geom_34" class="apartment_collision" size="0.25 0.43 0.008" pos="0.025 0 -0.164" type="box"/>
              <geom name="geom_35" class="apartment_collision" size="0.25 0.008 0.08" pos="0.025 -0.418 -0.075" type="box"/>
              <geom name="geom_36" class="apartment_collision" size="0.25 0.008 0.08" pos="0.025 0.418 -0.075" type="box"/>
              <geom name="geom_37" class="apartment_collision" size="0.008 0.41 0.08" pos="0.26 0 -0.075" type="box"/>
              <body gravcomp="1" name="cabinet11_drawer3_handle" pos="-0.267122 -0.00402777 0.151166" quat="0.707107 0.707107 0 0">
                <inertial pos="0.00608124 7.62691e-06 0.000219453" quat="0.707535 -0.0001654 -4.86875e-05 0.706679" mass="0.101418" diaginertia="0.000334346 0.000326533 1.03303e-05"/>
                <geom name="geom_38" class="apartment_visual" pos="0.00753596 3.13834e-07 -1.61273e-05" quat="0.707258 0.000144565 8.61629e-05 0.706956" type="mesh" mesh="SM_Kitchen_Handle"/>
                <geom name="geom_39" class="apartment_collision" size="0.01 0.0065 0.0065" pos="0.0164985 0 0.08" type="box"/>
                <geom name="geom_40" class="apartment_collision" size="0.0065 0.0065 0.086516" type="box"/>
                <geom name="geom_41" class="apartment_collision" size="0.01 0.0065 0.0065" pos="0.0164985 0 -0.08" type="box"/>
              </body>
            </body>
            <body gravcomp="1" name="cabinet11_drawer1" pos="-0.0508224 0.00063939 0.318169">
              <inertial pos="0.00621873 -2.29363e-07 -0.0222998" quat="0.507727 0.507728 -0.492151 0.492151" mass="90.8675" diaginertia="8.6329 6.49026 2.25642"/>
              <joint name="cabinet11_drawer1_joint" pos="0 0 0" axis="-1 0 0" type="slide" limited="true" range="0 0.45" actuatorfrclimited="false"/>
              <geom name="geom_42" class="apartment_visual" pos="0.00783624 -4.50262e-08 -0.0212394" quat="0.507658 0.507659 -0.492222 0.492223" type="mesh" material="SM_Kitchen_11_Drawer_01" mesh="SM_Kitchen_11_Drawer_01"/>
              <geom name="geom_43" class="apartment_collision" size="0.008 0.448 0.065" pos="-0.234 0 0" type="box"/>
              <geom name="geom_44" class="apartment_collision" size="0.25 0.43 0.008" pos="0.025 0 -0.045" type="box"/>
              <geom name="geom_45" class="apartment_collision" size="0.25 0.008 0.034" pos="0.025 -0.418 -0.005" type="box"/>
              <geom name="geom_46" class="apartment_collision" size="0.25 0.008 0.034" pos="0.025 0.418 -0.005" type="box"/>
              <geom name="geom_47" class="apartment_collision" size="0.008 0.41 0.034" pos="0.26 0 -0.005" type="box"/>
              <body gravcomp="1" name="cabinet11_drawer1_handle" pos="-0.266623 -0.00124599 0.0172039" quat="0.707107 0.707107 0 0">
                <inertial pos="0.00608124 7.62691e-06 0.000219453" quat="0.707535 -0.0001654 -4.86875e-05 0.706679" mass="0.101418" diaginertia="0.000334346 0.000326533 1.03303e-05"/>
                <geom name="geom_48" class="apartment_visual" pos="0.00753596 3.13834e-07 -1.61273e-05" quat="0.707258 0.000144565 8.61629e-05 0.706956" type="mesh" mesh="SM_Kitchen_Handle"/>
                <geom name="geom_49" class="apartment_collision" size="0.01 0.0065 0.0065" pos="0.0164985 0 0.08" type="box"/>
                <geom name="geom_50" class="apartment_collision" size="0.0065 0.0065 0.086516" type="box"/>
                <geom name="geom_51" class="apartment_collision" size="0.01 0.0065 0.0065" pos="0.0164985 0 -0.08" type="box"/>
              </body>
            </body>
            <body gravcomp="1" name="cabinet11_drawer2" pos="-0.0503088 0.0004598 0.119178">
              <inertial pos="-0.000397404 -4.60621e-07 -0.0510911" quat="0.52352 0.523521 -0.475316 0.475318" mass="148.509" diaginertia="13.4403 9.9447 4.37845"/>
              <joint name="cabinet11_drawer2_joint" pos="0 0 0" axis="-1 0 0" type="slide" limited="true" range="0 0.45" actuatorfrclimited="false"/>
              <geom name="geom_52" class="apartment_visual" pos="0.00167286 -6.44446e-07 -0.0499109" quat="0.523058 0.52306 -0.475824 0.475826" type="mesh" material="SM_Kitchen_11_Drawer_02" mesh="SM_Kitchen_11_Drawer_02"/>
              <geom name="geom_53" class="apartment_collision" size="0.008 0.448 0.13" pos="-0.234 0 0" type="box"/>
              <geom name="geom_54" class="apartment_collision" size="0.25 0.43 0.008" pos="0.025 0 -0.12" type="box"/>
              <geom name="geom_55" class="apartment_collision" size="0.25 0.008 0.08" pos="0.025 -0.418 -0.03" type="box"/>
              <geom name="geom_56" class="apartment_collision" size="0.25 0.008 0.08" pos="0.025 0.418 -0.03" type="box"/>
              <geom name="geom_57" class="apartment_collision" size="0.008 0.41 0.082" pos="0.26 0 -0.03" type="box"/>
              <body gravcomp="1" name="cabinet11_drawer2_handle" pos="-0.266862 -0.00397854 0.0854179" quat="0.707107 0.707107 0 0">
                <inertial pos="0.00608124 7.62691e-06 0.000219453" quat="0.707535 -0.0001654 -4.86875e-05 0.706679" mass="0.101418" diaginertia="0.000334346 0.000326533 1.03303e-05"/>
                <geom name="geom_58" class="apartment_visual" pos="0.00753596 3.13834e-07 -1.61273e-05" quat="0.707258 0.000144565 8.61629e-05 0.706956" type="mesh" mesh="SM_Kitchen_Handle"/>
                <geom name="geom_59" class="apartment_collision" size="0.01 0.0065 0.0065" pos="0.0164985 0 0.08" type="box"/>
                <geom name="geom_60" class="apartment_collision" size="0.0065 0.0065 0.086516" type="box"/>
                <geom name="geom_61" class="apartment_collision" size="0.01 0.0065 0.0065" pos="0.0164985 0 -0.08" type="box"/>
              </body>
            </body>
          </body>
          <body gravcomp="1" name="kitchen2_base_board" pos="2.21094 2.40968 0.0496364">
            <inertial pos="4.97141e-07 0.30216 -8.66057e-09" quat="0.707107 0.707107 0 0" mass="12.449" diaginertia="10.0649 10.0549 0.0107836"/>
            <geom name="geom_62" class="apartment_visual" pos="9.88935e-07 0.302021 -3.46449e-08" quat="0.707107 0.707107 0 0" type="mesh" material="SM_Kitchen_Base_Board_02" mesh="SM_Kitchen_Base_Board_02"/>
          </body>
          <body gravcomp="1" name="island_cover1" pos="2.86825 2.7196 0.450318">
            <inertial pos="3.60553e-10 -2.74205e-08 -3.51579e-10" quat="0.707107 0.707107 0 0" mass="111.33" diaginertia="98.8653 91.2825 7.58996"/>
            <geom name="geom_63" class="apartment_visual" pos="1.41372e-09 -1.07516e-07 -1.37854e-09" quat="0.707107 0.707107 0 0" type="mesh" material="SM_Kitchen_Island_Cover_01" mesh="SM_Kitchen_Island_Cover_01"/>
          </body>
          <body gravcomp="1" name="cabinet9" pos="2.49288 2.77269 0.494068">
            <inertial pos="0.0496469 2.23937e-05 -0.0627762" quat="0.99744 0.000372835 0.0715044 -4.08164e-05" mass="400.63" diaginertia="34.5288 26.8457 22.969"/>
            <geom name="geom_64" class="apartment_visual" pos="0.0499065 2.35715e-05 -0.0621768" quat="0.997432 0.000399206 0.0716161 -4.42207e-05" type="mesh" material="SM_Kitchen_09_Base" mesh="SM_Kitchen_09_Base"/>
            <body gravcomp="1" name="cabinet9_drawer3" pos="-0.0504523 -0.00167063 -0.196113">
              <inertial pos="-0.0220108 -6.431e-07 -0.0795975" quat="1.11116e-05 0.787047 -7.22533e-06 0.616893" mass="115.125" diaginertia="6.18025 3.83482 3.5993"/>
              <joint name="cabinet9_drawer3_joint" pos="0 0 0" axis="-1 0 0" type="slide" limited="true" range="0 0.45" actuatorfrclimited="false"/>
              <geom name="geom_65" class="apartment_visual" pos="-0.0192353 -5.28482e-07 -0.0790552" quat="1.61793e-05 0.7855 -1.10844e-05 0.618862" type="mesh" material="SM_Kitchen_09_Drawer_03" mesh="SM_Kitchen_09_Drawer_03"/>
              <geom name="geom_66" class="apartment_collision" size="0.008 0.298 0.2" pos="-0.234 0 0" type="box"/>
              <geom name="geom_67" class="apartment_collision" size="0.25 0.27 0.008" pos="0.025 0 -0.164" type="box"/>
              <geom name="geom_68" class="apartment_collision" size="0.25 0.008 0.08" pos="0.025 -0.27 -0.075" type="box"/>
              <geom name="geom_69" class="apartment_collision" size="0.25 0.008 0.08" pos="0.025 0.27 -0.075" type="box"/>
              <geom name="geom_70" class="apartment_collision" size="0.008 0.26 0.08" pos="0.26 0 -0.075" type="box"/>
              <body gravcomp="1" name="cabinet9_drawer3_handle" pos="-0.268882 0.00102875 0.15027" quat="0.707107 0.707107 0 0">
                <inertial pos="0.00608124 7.62691e-06 0.000219453" quat="0.707535 -0.0001654 -4.86875e-05 0.706679" mass="0.101418" diaginertia="0.000334346 0.000326533 1.03303e-05"/>
                <geom name="geom_71" class="apartment_visual" pos="0.00753596 3.13834e-07 -1.61273e-05" quat="0.707258 0.000144565 8.61629e-05 0.706956" type="mesh" mesh="SM_Kitchen_Handle"/>
                <geom name="geom_72" class="apartment_collision" size="0.01 0.0065 0.0065" pos="0.0164985 0 0.08" type="box"/>
                <geom name="geom_73" class="apartment_collision" size="0.0065 0.0065 0.086516" type="box"/>
                <geom name="geom_74" class="apartment_collision" size="0.01 0.0065 0.0065" pos="0.0164985 0 -0.08" type="box"/>
              </body>
            </body>
            <body gravcomp="1" name="cabinet9_drawer1" pos="-0.0507959 -0.00175364 0.332084">
              <inertial pos="0.00115867 -2.90281e-07 -0.0214327" quat="0.507161 0.50717 -0.492726 0.492734" mass="57.6743" diaginertia="3.09476 1.71648 1.4527"/>
              <joint name="cabinet9_drawer1_joint" pos="0 0 0" axis="-1 0 0" type="slide" limited="true" range="0 0.45" actuatorfrclimited="false"/>
              <geom name="geom_75" class="apartment_visual" pos="0.00216003 -4.02312e-07 -0.0203236" quat="0.506956 0.506965 -0.492937 0.492945" type="mesh" material="SM_Kitchen_09_Drawer_01" mesh="SM_Kitchen_09_Drawer_01"/>
              <geom name="geom_76" class="apartment_collision" size="0.008 0.298 0.065" pos="-0.234 0 0" type="box"/>
              <geom name="geom_77" class="apartment_collision" size="0.25 0.27 0.008" pos="0.025 0 -0.045" type="box"/>
              <geom name="geom_78" class="apartment_collision" size="0.25 0.008 0.034" pos="0.025 -0.27 -0.005" type="box"/>
              <geom name="geom_79" class="apartment_collision" size="0.25 0.008 0.034" pos="0.025 0.27 -0.005" type="box"/>
              <geom name="geom_80" class="apartment_collision" size="0.008 0.26 0.034" pos="0.26 0 -0.005" type="box"/>
              <body gravcomp="1" name="cabinet9_drawer1_handle" pos="-0.269809 0.00142363 0.0167695" quat="0.707107 0.707107 0 0">
                <inertial pos="0.00608124 7.62691e-06 0.000219453" quat="0.707535 -0.0001654 -4.86875e-05 0.706679" mass="0.101418" diaginertia="0.000334346 0.000326533 1.03303e-05"/>
                <geom name="geom_81" class="apartment_visual" pos="0.00753596 3.13834e-07 -1.61273e-05" quat="0.707258 0.000144565 8.61629e-05 0.706956" type="mesh" mesh="SM_Kitchen_Handle"/>
                <geom name="geom_82" class="apartment_collision" size="0.01 0.0065 0.0065" pos="0.0164985 0 0.08" type="box"/>
                <geom name="geom_83" class="apartment_collision" size="0.0065 0.0065 0.086516" type="box"/>
                <geom name="geom_84" class="apartment_collision" size="0.01 0.0065 0.0065" pos="0.0164985 0 -0.08" type="box"/>
              </body>
            </body>
            <body gravcomp="1" name="cabinet9_drawer2" pos="-0.050753 -0.00065196 0.134945">
              <inertial pos="-0.00180101 -6.37148e-07 -0.0503348" quat="0.52345 0.523541 -0.475304 0.475386" mass="98.0957" diaginertia="5.2413 2.9346 2.89318"/>
              <joint name="cabinet9_drawer2_joint" pos="0 0 0" axis="-1 0 0" type="slide" limited="true" range="0 0.45" actuatorfrclimited="false"/>
              <geom name="geom_85" class="apartment_visual" pos="0.000185324 -6.37643e-07 -0.0491402" quat="0.523037 0.523083 -0.475802 0.475845" type="mesh" material="SM_Kitchen_09_Drawer_02" mesh="SM_Kitchen_09_Drawer_02"/>
              <geom name="geom_86" class="apartment_collision" size="0.008 0.298 0.13" pos="-0.234 0 0" type="box"/>
              <geom name="geom_87" class="apartment_collision" size="0.25 0.27 0.008" pos="0.025 0 -0.12" type="box"/>
              <geom name="geom_88" class="apartment_collision" size="0.25 0.008 0.08" pos="0.025 -0.27 -0.03" type="box"/>
              <geom name="geom_89" class="apartment_collision" size="0.25 0.008 0.08" pos="0.025 0.27 -0.03" type="box"/>
              <geom name="geom_90" class="apartment_collision" size="0.008 0.26 0.082" pos="0.26 0 -0.03" type="box"/>
              <body gravcomp="1" name="cabinet9_drawer2_handle" pos="-0.270711 0.00106413 0.0850084" quat="0.707107 0.707107 0 0">
                <inertial pos="0.00608124 7.62691e-06 0.000219453" quat="0.707535 -0.0001654 -4.86875e-05 0.706679" mass="0.101418" diaginertia="0.000334346 0.000326533 1.03303e-05"/>
                <geom name="geom_91" class="apartment_visual" pos="0.00753596 3.13834e-07 -1.61273e-05" quat="0.707258 0.000144565 8.61629e-05 0.706956" type="mesh" mesh="SM_Kitchen_Handle"/>
                <geom name="geom_92" class="apartment_collision" size="0.01 0.0065 0.0065" pos="0.0164985 0 0.08" type="box"/>
                <geom name="geom_93" class="apartment_collision" size="0.0065 0.0065 0.086516" type="box"/>
                <geom name="geom_94" class="apartment_collision" size="0.01 0.0065 0.0065" pos="0.0164985 0 -0.08" type="box"/>
              </body>
            </body>
          </body>
          <body gravcomp="1" name="island_cover3" pos="2.53831 4.2773 0.45176">
            <inertial pos="7.31818e-07 -4.1024e-07 8.05494e-07" quat="0.707107 -1.37151e-06 -1.37151e-06 0.707107" mass="24.4738" diaginertia="2.59588 1.65554 0.941963"/>
            <geom name="geom_95" class="apartment_visual" pos="1.45982e-06 -8.22919e-07 1.62112e-06" quat="0.707107 -2.79638e-06 -2.79638e-06 0.707107" type="mesh" material="SM_Kitchen_Island_Cover_03" mesh="SM_Kitchen_Island_Cover_03"/>
          </body>
          <body gravcomp="1" name="counter_sink_stove" pos="2.65274 2.70904 0.465629">
            <inertial pos="0.00757222 -0.846144 0.200681" quat="0.452883 0.530683 -0.549041 0.460247" mass="1208.91" diaginertia="1145.07 1114.74 112.543"/>
            <geom name="geom_96" class="apartment_visual" pos="0.00138362 -0.931807 0.17245" quat="0.456514 0.540469 -0.541197 0.454526" type="mesh" material="SM_Counter_Sink_Stove" mesh="SM_Counter_Sink_Stove"/>
            <geom name="geom_97" class="apartment_collision" size="0.5 0.015 0.455" pos="0 -1.575 -0.015" type="box"/>
            <geom name="geom_98" class="apartment_collision" size="0.5 1.03 0.015" pos="0 -0.56 0.455" type="box"/>
            <geom name="geom_99" class="apartment_collision" size="0.05 0.19 0.015" pos="-0.45 0.66 0.455" type="box"/>
            <geom name="geom_100" class="apartment_collision" size="0.24 0.19 0.015" pos="0.26 0.66 0.455" type="box"/>
            <geom name="geom_101" class="apartment_collision" size="0.5 0.37 0.015" pos="0 1.22 0.455" type="box"/>
            <body gravcomp="1" name="counter_sink" pos="-0.188876 0.665534 0.382404">
              <inertial pos="0.00707683 8.28024e-07 -0.00878325" quat="-2.27772e-05 0.702345 2.68141e-05 0.711836" mass="55.4451" diaginertia="1.75035 1.09237 0.911852"/>
              <geom name="geom_102" class="apartment_visual" pos="-0.00815534 1.06121e-06 -0.00291717" quat="-6.27296e-05 0.70225 6.97832e-05 0.71193" type="mesh" material="SM_Counter_Sink" mesh="SM_Counter_Sink"/>
              <geom name="geom_103" class="apartment_collision" size="0.00973 0.20155 0.088265" pos="-0.212 0 0" type="box"/>
              <geom name="geom_104" class="apartment_collision" size="0.04 0.20155 0.088265" pos="0.182 0 0" type="box"/>
              <geom name="geom_105" class="apartment_collision" size="0.17201 0.00973 0.088265" pos="-0.0303 0.19182 0" type="box"/>
              <geom name="geom_106" class="apartment_collision" size="0.17201 0.00973 0.088265" pos="-0.0303 -0.19182 0" type="box"/>
              <geom name="geom_107" class="apartment_collision" size="0.17201 0.18209 0.013552" pos="-0.0303 0 -0.075" type="box"/>
              <body gravcomp="1" name="counter_watertab" pos="0.0767719 -0.0196184 0.238988">
                <inertial pos="0.0598216 0.0144469 0.0253963" quat="0.670131 -0.222187 -0.190982 0.68197" mass="1.85597" diaginertia="0.0243883 0.0214345 0.00399681"/>
                <geom name="geom_108" class="apartment_visual" pos="0.0504842 0.0143328 0.0353921" quat="0.660882 -0.243996 -0.205562 0.679298" type="mesh" material="SM_Counter_Watertab" mesh="SM_Counter_Watertab"/>
                <geom name="geom_109" class="apartment_collision" size="0.010966 0.003818" pos="-0.116237 0.0195 0.121328" type="cylinder"/>
                <geom name="geom_110" class="apartment_collision" size="0.022435 0.038739" pos="0.113704 0.0195 -0.11162" type="cylinder"/>
                <geom name="geom_111" class="apartment_collision" size="0.014 0.10908" pos="0.113704 0.0195 0.041404" type="cylinder"/>
                <geom name="geom_112" class="apartment_collision" size="0.014 0.131986" pos="-0.00425 0.019498 0.136485" quat="0.5 0.5 0.5 0.5" type="cylinder"/>
                <geom name="geom_113" class="apartment_collision" size="0.022466 0.044495" pos="0.113731 0.009 -0.073523" quat="0.5 -0.5 0.5 0.5" type="cylinder"/>
                <geom name="geom_114" class="apartment_collision" size="0.018" pos="0.113738 -0.035496 -0.073492"/>
                <body gravcomp="1" name="counter_sink_tap" pos="0.113711 -0.0405528 -0.0737045" quat="0 0 0 1">
                  <inertial pos="4.56119e-07 0.00948861 0.00544359" quat="0.70695 -0.0146711 0.0146713 0.706959" mass="0.0723926" diaginertia="3.43395e-05 2.90021e-05 1.14949e-05"/>
                  <geom name="geom_115" class="apartment_visual" pos="1.24268e-06 0.0115852 0.00606926" quat="0.707082 0.0059063 -0.0059063 0.707082" type="mesh" material="SM_Counter_Sink_Tap" mesh="SM_Counter_Sink_Tap"/>
                  <geom name="geom_116" class="apartment_collision" size="0.022432 0.012197" pos="0 0.007501 0" quat="0.5 -0.5 0.5 0.5" type="cylinder"/>
                  <geom name="geom_117" class="apartment_collision" size="0.005 0.027997" pos="0 0.012886 0.048989" type="cylinder"/>
                </body>
              </body>
            </body>
            <body gravcomp="1" name="stove" pos="-0.156557 -1.08145 0.471606">
              <inertial pos="0 0 0" quat="0.5 0.5 -0.5 0.5" mass="3.94313" diaginertia="0.295423 0.207865 0.0875728"/>
              <geom name="geom_118" class="apartment_visual" quat="0.5 0.5 -0.5 0.5" type="mesh" material="SM_Stove" mesh="SM_Stove"/>
            </body>
          </body>
          <body gravcomp="1" name="dishwasher" pos="2.32419 3.96355 0.162264">
            <inertial pos="0.197682 0.00830375 0.248289" quat="0.999806 -0.0111824 0.0161945 0.000132041" mass="423.287" diaginertia="37.6335 29.2975 22.9724"/>
            <geom name="geom_119" class="apartment_visual" pos="0.198639 0.00998765 0.290395" quat="0.999854 0.0026709 0.016884 -0.000201926" type="mesh" material="SM_Dishwasher_Base" mesh="SM_Dishwasher_Base"/>
            <body gravcomp="1" name="dishwasher_tray3" pos="0.227872 0.0131253 0.611314">
              <inertial pos="-0.00337429 0.000291387 0.00196981" quat="0.499517 0.500414 -0.499591 0.500476" mass="44.0744" diaginertia="1.61786 0.918197 0.722502"/>
              <joint name="dishwasher_tray3_joint" pos="0 0 0" axis="-1 0 0" type="slide" limited="true" range="0 0.3" actuatorfrclimited="false"/>
              <geom name="geom_120" class="apartment_visual" pos="-0.0055149 0.000476378 0.00321941" quat="0.498413 0.501257 -0.498733 0.501589" type="mesh" material="SM_Dishwasher_Tray_03" mesh="SM_Dishwasher_Tray_03"/>
              <geom name="geom_121" class="apartment_collision" size="0.22 0.27 0.036" type="box"/>
            </body>
            <body gravcomp="1" name="dishwasher_front" pos="-0.0761212 0.00031149 0.00728645" quat="0.707107 -0.707107 0 0">
              <inertial pos="-0.0146024 -0.347762 0.00697063" quat="0.713198 0.700959 0.00207819 -0.000584643" mass="68.2174" diaginertia="4.73037 2.92715 1.85856"/>
              <joint name="dishwasher_front_joint" pos="0 0 0" axis="0 0 -1" limited="true" range="0 1.5708" actuatorfrclimited="false" stiffness="0"/>
              <geom name="geom_122" class="apartment_visual" pos="-0.0108323 -0.354737 0.0139337" quat="0.71249 0.701679 0.00175603 -0.00132446" type="mesh" material="SM_Dishwasher_Front" mesh="SM_Dishwasher_Front"/>
              <geom name="geom_123" class="apartment_collision" size="0.015 0.339603 0.287469" pos="-0.01 -0.334215 0" type="box"/>
              <geom name="geom_124" class="apartment_collision" size="0.009444 0.397179 0.298" pos="-0.04 -0.329015 0.005" type="box"/>
              <body gravcomp="1" name="dishwasher_front_handle" pos="-0.0749352 -0.678848 0">
                <inertial pos="0.00608124 7.62691e-06 0.000219453" quat="0.707535 -0.0001654 -4.86875e-05 0.706679" mass="0.101418" diaginertia="0.000334346 0.000326533 1.03303e-05"/>
                <geom name="geom_125" class="apartment_visual" pos="0.00753596 3.13834e-07 -1.61273e-05" quat="0.707258 0.000144565 8.61629e-05 0.706956" type="mesh" mesh="SM_Kitchen_Handle"/>
                <geom name="geom_126" class="apartment_collision" size="0.01 0.0065 0.0065" pos="0.0164985 0 0.08" type="box"/>
                <geom name="geom_127" class="apartment_collision" size="0.0065 0.0065 0.086516" type="box"/>
                <geom name="geom_128" class="apartment_collision" size="0.01 0.0065 0.0065" pos="0.0164985 0 -0.08" type="box"/>
              </body>
            </body>
            <body gravcomp="1" name="dishwasher_tray1" pos="0.224014 0.00735926 0.227136">
              <inertial pos="-0.0489495 -0.00307208 -0.05411" quat="0.511168 0.521577 -0.474273 0.49166" mass="41.137" diaginertia="1.91603 1.31505 0.959636"/>
              <joint name="dishwasher_tray1_joint" pos="0 0 0" axis="-1 0 0" type="slide" limited="true" range="0 0.5" actuatorfrclimited="false"/>
              <geom name="geom_129" class="apartment_visual" pos="-0.0512381 -0.00385123 -0.0465177" quat="0.515152 0.52819 -0.466604 0.487765" type="mesh" material="SM_Dishwasher_Tray_01" mesh="SM_Dishwasher_Tray_01"/>
              <geom name="geom_130" class="apartment_collision" size="0.004289 0.269203 0.116486" pos="-0.280937 0 -0.035299" type="box"/>
              <geom name="geom_131" class="apartment_collision" size="0.242135 0.269203 0.007112" pos="-0.03859 0 -0.144673" type="box"/>
              <geom name="geom_132" class="apartment_collision" size="0.242135 0.005448 0.116486" pos="-0.03859 -0.255159 -0.035299" type="box"/>
              <geom name="geom_133" class="apartment_collision" size="0.242135 0.005448 0.116486" pos="-0.03859 0.255159 -0.035299" type="box"/>
              <geom name="geom_134" class="apartment_collision" size="0.004289 0.269203 0.116486" pos="0.193489 0 -0.035299" type="box"/>
            </body>
            <body gravcomp="1" name="dishwasher_tray2" pos="0.20742 0.00735798 0.402328">
              <inertial pos="-0.0074148 -0.00344249 0.00812695" quat="0.504771 0.520589 -0.482799 0.491017" mass="39.4614" diaginertia="1.55296 1.03752 0.748971"/>
              <joint name="dishwasher_tray2_joint" pos="0 0 0" axis="-1 0 0" type="slide" limited="true" range="0 0.3" actuatorfrclimited="false"/>
              <geom name="geom_135" class="apartment_visual" pos="-0.0100129 -0.00464878 0.018306" quat="0.505512 0.530028 -0.476129 0.486651" type="mesh" material="SM_Dishwasher_Tray_02" mesh="SM_Dishwasher_Tray_02"/>
              <geom name="geom_136" class="apartment_collision" size="0.231314 0.23732 0.013794" pos="0 0 -0.051928" type="box"/>
              <geom name="geom_137" class="apartment_collision" size="0.231314 0.008574 0.087812" pos="0 -0.243352 0.023995" type="box"/>
              <geom name="geom_138" class="apartment_collision" size="0.004182 0.23732 0.087812" pos="-0.225859 0 0.023995" type="box"/>
              <geom name="geom_139" class="apartment_collision" size="0.231314 0.008574 0.087812" pos="0 0.243352 0.023995" type="box"/>
              <geom name="geom_140" class="apartment_collision" size="0.004182 0.23732 0.087812" pos="0.225859 0 0.023995" type="box"/>
            </body>
          </body>
          <body gravcomp="1" name="island_cover5" pos="2.5375 1.16089 0.446014">
            <inertial pos="7.31818e-07 -4.1024e-07 8.05494e-07" quat="0.707107 -1.37151e-06 -1.37151e-06 0.707107" mass="24.4738" diaginertia="2.59588 1.65554 0.941963"/>
            <geom name="geom_141" class="apartment_visual" pos="1.45982e-06 -8.22919e-07 1.62112e-06" quat="0.707107 -2.79638e-06 -2.79638e-06 0.707107" type="mesh" mesh="SM_Kitchen_Island_Cover_03"/>
          </body>
          <body gravcomp="1" name="cabinet8" pos="2.49268 3.37232 0.494481">
            <inertial pos="0.0525295 1.44779e-05 -0.0755496" quat="0.996055 0.000472357 0.0887322 -7.85727e-05" mass="377.621" diaginertia="32.2762 25.0597 21.5471"/>
            <geom name="geom_142" class="apartment_visual" pos="0.052995 1.51886e-05 -0.0757485" quat="0.99588 0.000510259 0.0906743 -8.80048e-05" type="mesh" material="SM_Kitchen_08_Sink_Base" mesh="SM_Kitchen_08_Sink_Base"/>
            <body gravcomp="1" name="sink_drawer1" pos="-0.0508662 0.00013535 0.0032">
              <inertial pos="-0.0395069 0.0017839 -0.158877" quat="0.940243 -0.00541551 -0.340454 0.00194161" mass="292.209" diaginertia="15.2431 12.4046 10.5657"/>
              <joint name="sink_drawer1_joint" pos="0 0 0" axis="-1 0 0" type="slide" limited="true" range="0 0.45" actuatorfrclimited="false"/>
              <geom name="geom_143" class="apartment_visual" pos="-0.038416 0.00124692 -0.160811" quat="0.94072 -0.00513464 -0.339144 -0.000496146" type="mesh" material="SM_Kitchen_08_Sink_Drawer_01" mesh="SM_Kitchen_08_Sink_Drawer_01"/>
              <geom name="geom_144" class="apartment_collision" size="0.008426 0.154749 0.173305" pos="0.003041 -0.075302 -0.198155" type="box"/>
              <geom name="geom_145" class="apartment_collision" size="0.249028 0.031012 0.008" pos="0.025012 0.246033 -0.04" type="box"/>
              <geom name="geom_146" class="apartment_collision" size="0.249028 0.0075 0.011648" pos="0.025012 -0.268047 -0.208727" type="box"/>
              <geom name="geom_147" class="apartment_collision" size="0.074789 0.008426 0.173305" pos="0.086505 0.211412 -0.198155" type="box"/>
              <geom name="geom_148" class="apartment_collision" size="0.109729 0.154749 0.00085" pos="-0.098209 -0.075302 -0.372315" type="box"/>
              <geom name="geom_149" class="apartment_collision" size="0.009017 0.269754 0.084742" pos="0.259483 0 -0.288887" type="box"/>
              <geom name="geom_150" class="apartment_collision" size="0.109729 0.008426 0.173305" pos="-0.098209 0.221355 -0.198155" type="box"/>
              <geom name="geom_151" class="apartment_collision" size="0.008356 0.109826 0.173305" pos="0.152938 0.109826 -0.198155" type="box"/>
              <geom name="geom_152" class="apartment_collision" size="0.074789 0.008426 0.173305" pos="0.086505 -0.211412 -0.198155" type="box"/>
              <geom name="geom_153" class="apartment_collision" size="0.009388 0.285 0.397013" pos="-0.233976 0 0" type="box"/>
              <geom name="geom_154" class="apartment_collision" size="0.109729 0.008426 0.173305" pos="-0.098209 0.071323 -0.198155" type="box"/>
              <geom name="geom_155" class="apartment_collision" size="0.074789 0.109826 0.00085" pos="0.086505 0.109826 -0.372315" type="box"/>
              <geom name="geom_156" class="apartment_collision" size="0.008426 0.074691 0.173305" pos="0.003041 0.155 -0.198155" type="box"/>
              <geom name="geom_157" class="apartment_collision" size="0.249028 0.0075 0.042" pos="0.025012 0.268047 -0.08949" type="box"/>
              <geom name="geom_158" class="apartment_collision" size="0.008426 0.109826 0.173305" pos="0.152938 -0.109826 -0.198155" type="box"/>
              <geom name="geom_159" class="apartment_collision" size="0.074789 0.109826 0.00085" pos="0.086505 -0.109826 -0.372315" type="box"/>
              <geom name="geom_160" class="apartment_collision" size="0.058653 0.277046 0.008" pos="0.21583 0 -0.04" type="box"/>
              <geom name="geom_161" class="apartment_collision" size="0.008426 0.154749 0.173305" pos="-0.199821 -0.075302 -0.198155" type="box"/>
              <geom name="geom_162" class="apartment_collision" size="0.249028 0.0075 0.011648" pos="0.025012 0.268047 -0.208727" type="box"/>
              <geom name="geom_163" class="apartment_collision" size="0.010504 0.277046 0.008" pos="-0.213959 0 -0.04" type="box"/>
              <geom name="geom_164" class="apartment_collision" size="0.109729 0.008426 0.173305" pos="-0.098209 0.088435 -0.198155" type="box"/>
              <geom name="geom_165" class="apartment_collision" size="0.008426 0.109826 0.173305" pos="0.02 -0.109826 -0.198155" type="box"/>
              <geom name="geom_166" class="apartment_collision" size="0.074789 0.008426 0.173305" pos="0.086505 0.00535 -0.198155" type="box"/>
              <geom name="geom_167" class="apartment_collision" size="0.109729 0.008426 0.173305" pos="-0.098209 -0.221355 -0.198155" type="box"/>
              <geom name="geom_168" class="apartment_collision" size="0.109729 0.074691 0.00085" pos="-0.098209 0.155 -0.372315" type="box"/>
              <geom name="geom_169" class="apartment_collision" size="0.074789 0.008426 0.173305" pos="0.086505 -0.00535 -0.198155" type="box"/>
              <geom name="geom_170" class="apartment_collision" size="0.249028 0.031012 0.008" pos="0.025012 -0.246033 -0.04" type="box"/>
              <geom name="geom_171" class="apartment_collision" size="0.249028 0.0075 0.043609" pos="0.025012 -0.268047 -0.33085" type="box"/>
              <geom name="geom_172" class="apartment_collision" size="0.008426 0.074691 0.173305" pos="-0.199821 0.155 -0.198155" type="box"/>
              <geom name="geom_173" class="apartment_collision" size="0.249028 0.0075 0.042" pos="0.025012 -0.268047 -0.08949" type="box"/>
              <geom name="geom_174" class="apartment_collision" size="0.249028 0.0075 0.043609" pos="0.025012 0.268047 -0.33085" type="box"/>
              <geom name="geom_175" class="apartment_collision" size="0.008356 0.109826 0.173305" pos="0.02 0.109826 -0.198155" type="box"/>
              <body gravcomp="1" name="sink_drawer1_handle" pos="-0.269002 0.00331339 0.350717" quat="0.707107 0.707107 0 0">
                <inertial pos="0.00608124 7.62691e-06 0.000219453" quat="0.707535 -0.0001654 -4.86875e-05 0.706679" mass="0.101418" diaginertia="0.000334346 0.000326533 1.03303e-05"/>
                <geom name="geom_176" class="apartment_visual" pos="0.00753596 3.13834e-07 -1.61273e-05" quat="0.707258 0.000144565 8.61629e-05 0.706956" type="mesh" mesh="SM_Kitchen_Handle"/>
                <geom name="geom_177" class="apartment_collision" size="0.01 0.0065 0.0065" pos="0.0164985 0 0.08" type="box"/>
                <geom name="geom_178" class="apartment_collision" size="0.0065 0.0065 0.086516" type="box"/>
                <geom name="geom_179" class="apartment_collision" size="0.01 0.0065 0.0065" pos="0.0164985 0 -0.08" type="box"/>
              </body>
            </body>
            <body gravcomp="1" name="sink_drawer2" pos="-0.0729948 0.00142344 0.164377">
              <inertial pos="-0.00278189 0.000215684 -0.0140502" quat="0.501677 0.501445 -0.498547 0.498321" mass="43.0728" diaginertia="1.89029 1.30448 0.627469"/>
              <joint name="sink_drawer2_joint" pos="0 0 0" axis="-1 0 0" type="slide" limited="true" range="0 0.3" actuatorfrclimited="false"/>
              <geom name="geom_180" class="apartment_visual" pos="-0.00233147 0.000250779 -0.01294" quat="0.501507 0.501236 -0.498751 0.498498" type="mesh" material="SM_Kitchen_08_Sink_Drawer_02" mesh="SM_Kitchen_08_Sink_Drawer_02"/>
            </body>
          </body>
        </body>
        <body gravcomp="1" name="kitchen1_root">
          <inertial pos="0 0 0" mass="1e-06" diaginertia="1e-06 1e-06 1e-06"/>
          <body gravcomp="1" name="cabinet4" pos="0.182244 3.29388 1.82711" quat="0 0 0 1">
            <inertial pos="0.0304404 -0.0538297 0.00660099" quat="0.703958 0.710205 -0.0068971 -0.00202589" mass="586.321" diaginertia="91.5721 64.8488 35.6414"/>
            <geom name="geom_181" class="apartment_visual" pos="0.0297395 -0.0521675 0.00699203" quat="0.703796 0.710369 -0.00667218 -0.00142911" type="mesh" material="SM_Kitchen_04_Base" mesh="SM_Kitchen_04_Base"/>
            <body gravcomp="1" name="cabinet4_shelf2" pos="0.00833792 -0.0101648 -0.0984018">
              <inertial pos="1.03009e-07 9.76302e-08 2.4221e-07" quat="0.5 0.5 -0.5 0.5" mass="4.81165" diaginertia="0.413506 0.375625 0.0379337"/>
              <geom name="geom_182" class="apartment_visual" pos="2.0289e-07 1.81402e-07 4.83769e-07" quat="0.5 0.5 -0.5 0.5" type="mesh" mesh="SM_Kitchen_04_Shelf"/>
            </body>
            <body gravcomp="1" name="cabinet4_door2" pos="-0.150429 0.0093109 -0.199949">
              <inertial pos="-0.0234435 1.89998e-06 0.00498029" quat="0.707106 0.707104 0.00168958 -0.00169057" mass="16.6041" diaginertia="1.64715 1.44437 0.205395"/>
              <geom name="geom_183" class="apartment_visual" pos="-0.021873 2.96149e-06 0.00906418" quat="0.707103 0.707099 0.00282335 -0.00282505" type="mesh" material="SM_Kitchen_04_Door_02" mesh="SM_Kitchen_04_Door_02"/>
              <body gravcomp="1" name="cabinet4_door2_handle" pos="-0.0610386 -0.014152 -0.133571" quat="0.707107 0.707107 0 0">
                <inertial pos="0.00608124 7.62691e-06 0.000219453" quat="0.707535 -0.0001654 -4.86875e-05 0.706679" mass="0.101418" diaginertia="0.000334346 0.000326533 1.03303e-05"/>
                <geom name="geom_184" class="apartment_visual" pos="0.00753596 3.13834e-07 -1.61273e-05" quat="0.707258 0.000144565 8.61629e-05 0.706956" type="mesh" mesh="SM_Kitchen_Handle"/>
              </body>
            </body>
            <body gravcomp="1" name="cabinet4_shelf1" pos="0.00833792 -0.0101648 0.125006">
              <inertial pos="1.03009e-07 9.76302e-08 2.4221e-07" quat="0.5 0.5 -0.5 0.5" mass="4.81165" diaginertia="0.413506 0.375625 0.0379337"/>
              <geom name="geom_185" class="apartment_visual" pos="2.0289e-07 1.81402e-07 4.83769e-07" quat="0.5 0.5 -0.5 0.5" type="mesh" mesh="SM_Kitchen_04_Shelf"/>
            </body>
            <body gravcomp="1" name="cabinet4_door1" pos="-0.172261 0.00837158 0.199167">
              <inertial pos="-0.00274103 1.38144e-06 0.00406009" quat="0.707106 0.707108 0.00054495 -0.000544951" mass="15.4558" diaginertia="1.49239 1.28871 0.204618"/>
              <geom name="geom_186" class="apartment_visual" pos="-0.00259659 2.39565e-06 0.00786826" quat="0.707104 0.707108 0.00101651 -0.00101652" type="mesh" material="SM_Kitchen_04_Door_01" mesh="SM_Kitchen_04_Door_01"/>
            </body>
          </body>
          <body gravcomp="1" name="cabinet6" pos="0.274766 3.58384 0.494207" quat="0 0 0 1">
            <inertial pos="0.0450371 0.000277177 -0.0594252" quat="0.703774 0.0467616 0.0460588 0.707385" mass="275.729" diaginertia="18.6947 17.9737 9.98513"/>
            <geom name="geom_187" class="apartment_visual" pos="0.0458732 0.000298986 -0.059823" quat="0.703696 0.048073 0.0473212 0.707291" type="mesh" material="SM_Kitchen_06_Base" mesh="SM_Kitchen_06_Base"/>
            <body gravcomp="1" name="cabinet6_drawer3" pos="-0.0527976 -0.00069453 -0.1971">
              <inertial pos="-0.0240704 -8.07589e-07 -0.078561" quat="5.04155e-06 0.786789 3.34045e-06 0.617222" mass="76.1255" diaginertia="2.93394 2.53493 1.23062"/>
              <joint name="cabinet6_drawer3_joint" pos="0 0 0" axis="-1 0 0" type="slide" limited="true" range="0 0.45" actuatorfrclimited="false"/>
              <geom name="geom_188" class="apartment_visual" pos="-0.0218304 -1.31845e-06 -0.0777047" quat="5.34113e-06 0.785522 3.22518e-06 0.618834" type="mesh" material="SM_Kitchen_06_Drawer_03" mesh="SM_Kitchen_06_Drawer_03"/>
              <geom name="geom_189" class="apartment_collision" size="0.008 0.2 0.2" pos="-0.234 0 0" type="box"/>
              <geom name="geom_190" class="apartment_collision" size="0.25 0.18 0.008" pos="0.025 0 -0.164" type="box"/>
              <geom name="geom_191" class="apartment_collision" size="0.25 0.008 0.08" pos="0.025 -0.17 -0.075" type="box"/>
              <geom name="geom_192" class="apartment_collision" size="0.25 0.008 0.08" pos="0.025 0.17 -0.075" type="box"/>
              <geom name="geom_193" class="apartment_collision" size="0.008 0.16 0.08" pos="0.26 0 -0.075" type="box"/>
              <body gravcomp="1" name="cabinet6_drawer3_handle" pos="-0.267122 -0.00402777 0.151166" quat="0.707107 0.707107 0 0">
                <inertial pos="0.00608124 7.62691e-06 0.000219453" quat="0.707535 -0.0001654 -4.86875e-05 0.706679" mass="0.101418" diaginertia="0.000334346 0.000326533 1.03303e-05"/>
                <geom name="geom_194" class="apartment_visual" pos="0.00753596 3.13834e-07 -1.61273e-05" quat="0.707258 0.000144565 8.61629e-05 0.706956" type="mesh" mesh="SM_Kitchen_Handle"/>
                <geom name="geom_195" class="apartment_collision" size="0.01 0.0065 0.0065" pos="0.0164985 0 0.08" type="box"/>
                <geom name="geom_196" class="apartment_collision" size="0.0065 0.0065 0.086516" type="box"/>
                <geom name="geom_197" class="apartment_collision" size="0.01 0.0065 0.0065" pos="0.0164985 0 -0.08" type="box"/>
              </body>
            </body>
            <body gravcomp="1" name="cabinet6_drawer1" pos="-0.053296 -0.00032649 0.331778">
              <inertial pos="0.00345742 -4.81613e-07 -0.0212922" quat="2.30621e-06 0.71773 -2.23742e-06 0.696321" mass="39.0767" diaginertia="1.42835 0.98064 0.497708"/>
              <joint name="cabinet6_drawer1_joint" pos="0 0 0" axis="-1 0 0" type="slide" limited="true" range="0 0.45" actuatorfrclimited="false"/>
              <geom name="geom_198" class="apartment_visual" pos="0.00458842 -5.53513e-07 -0.0202851" quat="4.37941e-06 0.717731 -4.24878e-06 0.696321" type="mesh" material="SM_Kitchen_06_Drawer_01" mesh="SM_Kitchen_06_Drawer_01"/>
              <geom name="geom_199" class="apartment_collision" size="0.008 0.2 0.065" pos="-0.234 0 0" type="box"/>
              <geom name="geom_200" class="apartment_collision" size="0.25 0.18 0.008" pos="0.025 0 -0.045" type="box"/>
              <geom name="geom_201" class="apartment_collision" size="0.25 0.008 0.034" pos="0.025 -0.17 -0.005" type="box"/>
              <geom name="geom_202" class="apartment_collision" size="0.25 0.008 0.034" pos="0.025 0.17 -0.005" type="box"/>
              <geom name="geom_203" class="apartment_collision" size="0.008 0.16 0.034" pos="0.26 0 -0.005" type="box"/>
              <body gravcomp="1" name="cabinet6_drawer1_handle" pos="-0.266623 -0.00124599 0.0172039" quat="0.707107 0.707107 0 0">
                <inertial pos="0.00608124 7.62691e-06 0.000219453" quat="0.707535 -0.0001654 -4.86875e-05 0.706679" mass="0.101418" diaginertia="0.000334346 0.000326533 1.03303e-05"/>
                <geom name="geom_204" class="apartment_visual" pos="0.00753596 3.13834e-07 -1.61273e-05" quat="0.707258 0.000144565 8.61629e-05 0.706956" type="mesh" mesh="SM_Kitchen_Handle"/>
                <geom name="geom_205" class="apartment_collision" size="0.01 0.0065 0.0065" pos="0.0164985 0 0.08" type="box"/>
                <geom name="geom_206" class="apartment_collision" size="0.0065 0.0065 0.086516" type="box"/>
                <geom name="geom_207" class="apartment_collision" size="0.01 0.0065 0.0065" pos="0.0164985 0 -0.08" type="box"/>
              </body>
            </body>
            <body gravcomp="1" name="cabinet6_drawer2" pos="-0.0530569 -0.00074397 0.1345">
              <inertial pos="-0.00359727 -7.25506e-07 -0.0493716" quat="3.35264e-06 0.74018 -2.15234e-07 0.672408" mass="64.8515" diaginertia="2.43881 1.91489 0.915224"/>
              <joint name="cabinet6_drawer2_joint" pos="0 0 0" axis="-1 0 0" type="slide" limited="true" range="0 0.45" actuatorfrclimited="false"/>
              <geom name="geom_208" class="apartment_visual" pos="-0.00200047 -6.44688e-07 -0.0480222" quat="3.87893e-06 0.739724 -2.86765e-07 0.67291" type="mesh" material="SM_Kitchen_06_Drawer_02" mesh="SM_Kitchen_06_Drawer_02"/>
              <geom name="geom_209" class="apartment_collision" size="0.008 0.2 0.13" pos="-0.234 0 0" type="box"/>
              <geom name="geom_210" class="apartment_collision" size="0.25 0.18 0.008" pos="0.025 0 -0.12" type="box"/>
              <geom name="geom_211" class="apartment_collision" size="0.25 0.008 0.08" pos="0.025 -0.17 -0.03" type="box"/>
              <geom name="geom_212" class="apartment_collision" size="0.25 0.008 0.08" pos="0.025 0.17 -0.03" type="box"/>
              <geom name="geom_213" class="apartment_collision" size="0.008 0.16 0.082" pos="0.26 0 -0.03" type="box"/>
              <body gravcomp="1" name="cabinet6_drawer2_handle" pos="-0.266862 -0.00397854 0.0854179" quat="0.707107 0.707107 0 0">
                <inertial pos="0.00608124 7.62691e-06 0.000219453" quat="0.707535 -0.0001654 -4.86875e-05 0.706679" mass="0.101418" diaginertia="0.000334346 0.000326533 1.03303e-05"/>
                <geom name="geom_214" class="apartment_visual" pos="0.00753596 3.13834e-07 -1.61273e-05" quat="0.707258 0.000144565 8.61629e-05 0.706956" type="mesh" mesh="SM_Kitchen_Handle"/>
                <geom name="geom_215" class="apartment_collision" size="0.01 0.0065 0.0065" pos="0.0164985 0 0.08" type="box"/>
                <geom name="geom_216" class="apartment_collision" size="0.0065 0.0065 0.086516" type="box"/>
                <geom name="geom_217" class="apartment_collision" size="0.01 0.0065 0.0065" pos="0.0164985 0 -0.08" type="box"/>
              </body>
            </body>
          </body>
          <body gravcomp="1" name="island_cover4" pos="0.272592 3.79516 0.446017" quat="0 0 0 1">
            <inertial pos="6.62726e-07 -4.2145e-07 8.30614e-07" quat="0.707107 -9.57798e-07 -9.57798e-07 0.707107" mass="20.8123" diaginertia="2.00682 1.39754 0.610604"/>
            <geom name="geom_218" class="apartment_visual" pos="1.08268e-06 -6.45598e-07 1.74329e-06" quat="0.707107 -1.87053e-06 -1.87053e-06 0.707107" type="mesh" material="SM_Kitchen_Island_Cover_04" mesh="SM_Kitchen_Island_Cover_04"/>
          </body>
          <body gravcomp="1" name="kitchen1_base_board" pos="0.55976 2.47826 0.0516843" quat="0 0 0 1">
            <inertial pos="-4.98967e-07 -5.18885e-08 -1.07685e-08" quat="0.707107 0.707107 0 0" mass="10.3521" diaginertia="5.85488 5.84659 0.00896343"/>
            <geom name="geom_219" class="apartment_visual" pos="-9.85541e-07 -2.06462e-07 -4.28464e-08" quat="0.707107 0.707107 0 0" type="mesh" material="SM_Kitchen_Base_Board_01" mesh="SM_Kitchen_Base_Board_01"/>
          </body>
          <body gravcomp="1" name="cabinet1" pos="0.284632 1.46676 1.11441" quat="0 0 0 1">
            <inertial pos="0.0213063 0.0295025 0.22533" quat="0.999626 0.0113613 -0.00492704 0.0243689" mass="1469.75" diaginertia="539.959 511.156 82.8589"/>
            <geom name="geom_220" class="apartment_visual" pos="0.0205866 0.0260717 0.23315" quat="0.999663 0.0104378 -0.00478458 0.0232644" type="mesh" material="SM_Kitchen_01_Base" mesh="SM_Kitchen_01_Base"/>
            <geom name="geom_221" class="apartment_collision" size="0.27 0.29 0.0495" pos="0.005 0 1.066" type="box"/>
            <geom name="geom_222" class="apartment_collision" size="0.0045 0.309 1.113" pos="0.284 0 0" type="box"/>
            <geom name="geom_223" class="apartment_collision" size="0.27 0.29 0.0075" pos="0.005 0 -0.36" type="box"/>
            <geom name="geom_224" class="apartment_collision" size="0.27 0.0045 1.113" pos="0.005 -0.3 0" type="box"/>
            <geom name="geom_225" class="apartment_collision" size="0.27 0.0045 1.113" pos="0.005 0.3 0" type="box"/>
            <body gravcomp="1" name="cabinet1_door" pos="-0.28 0.28 0.677">
              <inertial pos="-0.000206312 -0.280136 9.70059e-05" quat="0.999999 -0.00115473 2.98205e-07 -0.000392372" mass="20.1569" diaginertia="1.8725 1.26731 0.606422"/>
              <joint name="cabinet1_door_joint" pos="0 0 0" axis="0 0 -1" limited="true" range="0 1.5708" actuatorfrclimited="false"/>
              <geom name="geom_226" class="apartment_visual" pos="-0.00040266 -0.275419 0.000189119" quat="0.999997 -0.00224599 8.46851e-07 -0.000789775" type="mesh" material="SM_Kitchen_01_Door_01" mesh="SM_Kitchen_01_Door_01"/>
              <geom name="geom_227" class="apartment_collision" size="0.01 0.29 0.43" pos="0 -0.285 0" type="box"/>
              <body gravcomp="1" name="cabinet1_door_handle" pos="-0.0359888 -0.463156 -0.389834" quat="0.707107 0.707107 0 0">
                <inertial pos="0.00608124 7.62691e-06 0.000219453" quat="0.707535 -0.0001654 -4.86875e-05 0.706679" mass="0.101418" diaginertia="0.000334346 0.000326533 1.03303e-05"/>
                <geom name="geom_228" class="apartment_visual" pos="0.00753596 3.13834e-07 -1.61273e-05" quat="0.707258 0.000144565 8.61629e-05 0.706956" type="mesh" mesh="SM_Kitchen_Handle"/>
                <geom name="geom_229" class="apartment_collision" size="0.01 0.0065 0.0065" pos="0.0164985 0 0.08" type="box"/>
                <geom name="geom_230" class="apartment_collision" size="0.0065 0.0065 0.086516" type="box"/>
                <geom name="geom_231" class="apartment_collision" size="0.01 0.0065 0.0065" pos="0.0164985 0 -0.08" type="box"/>
              </body>
            </body>
            <body gravcomp="1" name="cabinet1_drawer1" pos="-0.0467902 -0.0112201 -0.4865">
              <inertial pos="-0.00194179 -0.00632324 -0.050175" quat="0.044059 0.739258 -0.0394735 0.670819" mass="95.2517" diaginertia="5.06798 2.86467 2.78935"/>
              <joint name="cabinet1_drawer1_joint" pos="0 0 0" axis="-1 0 0" type="slide" limited="true" range="0 0.45" actuatorfrclimited="false"/>
              <geom name="geom_232" class="apartment_visual" pos="-0.000402663 -0.0063309 -0.0490105" quat="0.24465 0.69856 -0.221949 0.634743" type="mesh" material="SM_Kitchen_01_Drawer_01" mesh="SM_Kitchen_01_Drawer_01"/>
              <geom name="geom_233" class="apartment_collision" size="0.008 0.298 0.13" pos="-0.234 0 0" type="box"/>
              <geom name="geom_234" class="apartment_collision" size="0.25 0.27 0.008" pos="0.025 0 -0.12" type="box"/>
              <geom name="geom_235" class="apartment_collision" size="0.25 0.008 0.08" pos="0.025 -0.27 -0.03" type="box"/>
              <geom name="geom_236" class="apartment_collision" size="0.25 0.008 0.08" pos="0.025 0.27 -0.03" type="box"/>
              <geom name="geom_237" class="apartment_collision" size="0.008 0.26 0.082" pos="0.26 0 -0.03" type="box"/>
              <body gravcomp="1" name="cabinet1_drawer1_handle" pos="-0.268318 0.00091816 0.0840143" quat="0.707107 0.707107 0 0">
                <inertial pos="0.00608124 7.62691e-06 0.000219453" quat="0.707535 -0.0001654 -4.86875e-05 0.706679" mass="0.101418" diaginertia="0.000334346 0.000326533 1.03303e-05"/>
                <geom name="geom_238" class="apartment_visual" pos="0.00753596 3.13834e-07 -1.61273e-05" quat="0.707258 0.000144565 8.61629e-05 0.706956" type="mesh" mesh="SM_Kitchen_Handle"/>
                <geom name="geom_239" class="apartment_collision" size="0.01 0.0065 0.0065" pos="0.0164985 0 0.08" type="box"/>
                <geom name="geom_240" class="apartment_collision" size="0.0065 0.0065 0.086516" type="box"/>
                <geom name="geom_241" class="apartment_collision" size="0.01 0.0065 0.0065" pos="0.0164985 0 -0.08" type="box"/>
              </body>
            </body>
            <body gravcomp="1" name="cabinet1_drawer2" pos="-0.046 -0.011 -0.817">
              <inertial pos="-0.0217808 -6.29426e-07 -0.0788672" quat="1.00276e-05 0.785788 -6.4729e-06 0.618497" mass="114.787" diaginertia="6.15113 3.81697 3.57506"/>
              <joint name="cabinet1_drawer2_joint" pos="0 0 0" axis="-1 0 0" type="slide" limited="true" range="0 0.45" actuatorfrclimited="false"/>
              <geom name="geom_242" class="apartment_visual" pos="-0.0190412 -8.86034e-07 -0.0785558" quat="1.83353e-05 0.78472 -1.28939e-05 0.61985" type="mesh" material="SM_Kitchen_01_Drawer_02" mesh="SM_Kitchen_01_Drawer_02"/>
              <geom name="geom_243" class="apartment_collision" size="0.008 0.298 0.2" pos="-0.234 0 0" type="box"/>
              <geom name="geom_244" class="apartment_collision" size="0.25 0.27 0.008" pos="0.025 0 -0.164" type="box"/>
              <geom name="geom_245" class="apartment_collision" size="0.25 0.008 0.08" pos="0.025 -0.27 -0.075" type="box"/>
              <geom name="geom_246" class="apartment_collision" size="0.25 0.008 0.08" pos="0.025 0.27 -0.075" type="box"/>
              <geom name="geom_247" class="apartment_collision" size="0.008 0.26 0.08" pos="0.26 0 -0.075" type="box"/>
              <body gravcomp="1" name="cabinet1_drawer2_handle" pos="-0.269483 -0.00145845 0.150606" quat="0.707107 0.707107 0 0">
                <inertial pos="0.00608124 7.62691e-06 0.000219453" quat="0.707535 -0.0001654 -4.86875e-05 0.706679" mass="0.101418" diaginertia="0.000334346 0.000326533 1.03303e-05"/>
                <geom name="geom_248" class="apartment_visual" pos="0.00753596 3.13834e-07 -1.61273e-05" quat="0.707258 0.000144565 8.61629e-05 0.706956" type="mesh" mesh="SM_Kitchen_Handle"/>
                <geom name="geom_249" class="apartment_collision" size="0.01 0.0065 0.0065" pos="0.0164985 0 0.08" type="box"/>
                <geom name="geom_250" class="apartment_collision" size="0.0065 0.0065 0.086516" type="box"/>
                <geom name="geom_251" class="apartment_collision" size="0.01 0.0065 0.0065" pos="0.0164985 0 -0.08" type="box"/>
              </body>
            </body>
            <body gravcomp="1" name="cabinet1_shelf1" pos="0.009901 0.0005 0.56">
              <inertial pos="0 0 0" quat="0 0.707107 0 0.707107" mass="9.01813" diaginertia="0.452362 0.237477 0.215224"/>
              <geom name="geom_252" class="apartment_visual" size="0.280969 0.267471 0.0075" type="box"/>
              <geom name="geom_253" class="apartment_collision" size="0.27 0.29 0.0075" pos="0.005 0 0" type="box"/>
            </body>
            <body gravcomp="1" name="cabinet1_shelf2" pos="0.009901 0.0005 0.249501">
              <inertial pos="0 0 0" quat="0.5 0.5 -0.5 0.5" mass="9.01813" diaginertia="0.452362 0.22635 0.22635"/>
              <geom name="geom_254" class="apartment_visual" size="0.280969 0.267471 0.0075" type="box"/>
              <geom name="geom_255" class="apartment_collision" size="0.27 0.29 0.0075" pos="0.005 0 0" type="box"/>
            </body>
            <body gravcomp="1" name="oven" pos="-0.273959 -0.0123597 -0.342672">
              <inertial pos="0.271003 0.0214719 0.311526" quat="0.947246 0.0725023 -0.308574 0.0474481" mass="509.902" diaginertia="31.1422 26.6737 25.9721"/>
              <geom name="geom_256" class="apartment_visual" pos="0.257216 0.00299401 0.301757" quat="0.931972 0.000367508 -0.36253 0.00012596" type="mesh" material="SM_Oven" mesh="SM_Oven"/>
              <geom name="geom_257" class="apartment_collision" size="0.279 0.293 0.295" pos="0.27 0 0.29" type="box"/>
              <body gravcomp="1" name="oven_door" quat="0.5 0.5 0.5 -0.5">
                <inertial pos="-0.22756 0.00487861 -0.00299939" quat="0.707403 -1.19075e-05 -1.18975e-05 0.70681" mass="30.6683" diaginertia="1.35034 0.807006 0.549358"/>
                <geom name="geom_258" class="apartment_visual" pos="-0.227966 0.00461727 -0.00300274" quat="0.707569 -2.07589e-05 -2.07318e-05 0.706644" type="mesh" material="SM_Oven" mesh="SM_Oven_Door"/>
              </body>
            </body>
          </body>
          <body gravcomp="1" name="counter_wall" pos="0.281428 3.29494 0.908921" quat="0 0 0 1">
            <inertial pos="0 -0.000610848 -0.000217012" quat="0.5 0.5 -0.5 0.5" mass="34.3508" diaginertia="4.06759 3.04112 1.03092"/>
            <geom name="geom_259" class="apartment_visual" pos="0 -0.001178 -0.000418004" quat="0.5 0.5 -0.5 0.5" type="mesh" material="SM_Counter_Wall" mesh="SM_Counter_Wall"/>
            <geom name="geom_260" class="apartment_collision" size="0.3 0.514 0.014" type="box"/>
          </body>
          <body gravcomp="1" name="cabinet3" pos="0.274985 2.4799 1.16288" quat="0 0 0 1">
            <inertial pos="-0.00917743 0.000664228 0.106976" quat="0.999978 -0.000439204 -0.00440195 -0.00496082" mass="1433.94" diaginertia="683.213 662.541 67.2436"/>
            <geom name="geom_261" class="apartment_visual" pos="-0.00921366 0.000728408 0.108197" quat="0.999976 -0.000432441 -0.00415521 -0.00543847" type="mesh" material="SM_Kitchen_03_Fridge" mesh="SM_Kitchen_03_Fridge"/>
            <geom name="geom_262" class="apartment_collision" size="0.27 0.29 0.125" pos="0.005 0 0.9365" type="box"/>
            <geom name="geom_263" class="apartment_collision" size="0.0045 0.309 1.0575" pos="0.284 0 0.002358" type="box"/>
            <geom name="geom_264" class="apartment_collision" size="0.27 0.29 0.0495" pos="0.005 0 -1.019" type="box"/>
            <geom name="geom_265" class="apartment_collision" size="0.27 0.0045 1.0575" pos="0.005 -0.3 0.002358" type="box"/>
            <geom name="geom_266" class="apartment_collision" size="0.27 0.0045 1.0575" pos="0.005 0.3 0.002358" type="box"/>
            <body gravcomp="1" name="fridge_door2" pos="-0.297259 0.29909 -0.638008">
              <inertial pos="0.0272184 -0.289822 0.00225719" quat="0.999984 -0.00378931 0.00424686 -0.000328652" mass="56.712" diaginertia="3.73385 2.23061 1.53597"/>
              <joint name="fridge_door2_joint" pos="0 0 0" axis="0 0 -1" limited="true" range="0 1.5708" actuatorfrclimited="false"/>
              <geom name="geom_267" class="apartment_visual" pos="0.0297624 -0.286934 0.0052645" quat="0.999983 -0.00428362 0.00398087 8.139e-05" type="mesh" material="SM_Fridge_Door_02" mesh="SM_Fridge_Door_02"/>
              <geom name="geom_268" class="apartment_collision" size="0.008 0.3 0.39" pos="0.007 -0.3 -0.028" type="box"/>
              <body gravcomp="1" name="fridge_door2_handle" pos="-0.0280466 -0.465383 0.317868" quat="0.707107 0.707107 0 0">
                <inertial pos="0.00608124 7.62691e-06 0.000219453" quat="0.707535 -0.0001654 -4.86875e-05 0.706679" mass="0.101418" diaginertia="0.000334346 0.000326533 1.03303e-05"/>
                <geom name="geom_269" class="apartment_visual" pos="0.00753596 3.13834e-07 -1.61273e-05" quat="0.707258 0.000144565 8.61629e-05 0.706956" type="mesh" mesh="SM_Kitchen_Handle"/>
                <geom name="geom_270" class="apartment_collision" size="0.01 0.0065 0.0065" pos="0.0164985 0 0.08" type="box"/>
                <geom name="geom_271" class="apartment_collision" size="0.0065 0.0065 0.086516" type="box"/>
                <geom name="geom_272" class="apartment_collision" size="0.01 0.0065 0.0065" pos="0.0164985 0 -0.08" type="box"/>
              </body>
            </body>
            <body gravcomp="1" name="fridge_base" pos="-0.0191809 -0.00292496 -0.0816938">
              <inertial pos="-0.00163932 0.00185957 0.104922" quat="0.999965 0.00035368 0.000113253 0.00841136" mass="953.573" diaginertia="258.907 244.266 41.5204"/>
              <geom name="geom_273" class="apartment_visual" pos="-0.0107466 0.00232395 0.147102" quat="0.999882 0.000910129 0.0116841 0.00990899" type="mesh" material="SM_Fridge_Base" mesh="SM_Fridge_Base"/>
              <geom name="geom_274" class="apartment_collision" size="0.196424 0.012277 0.318196" pos="-0.029351 -0.223235 -0.561142" type="box"/>
              <geom name="geom_275" class="apartment_collision" size="0.241826 0.021622 0.879405" pos="0.016051 -0.257778 0" type="box"/>
              <geom name="geom_276" class="apartment_collision" size="0.196424 0.234783 0.0125" pos="-0.029351 0 0.224975" type="box"/>
              <geom name="geom_277" class="apartment_collision" size="0.196424 0.234783 0.036788" pos="-0.029351 0 -0.842617" type="box"/>
              <geom name="geom_278" class="apartment_collision" size="0.196424 0.234783 0.03771" pos="-0.029351 0 0.839695" type="box"/>
              <geom name="geom_279" class="apartment_collision" size="0.00782 0.234783 0.464658" pos="0.17 0 0.339754" type="box"/>
              <geom name="geom_280" class="apartment_collision" size="0.246695 0.278217 0.023998" pos="0.011034 0 0.855407" type="box"/>
              <geom name="geom_281" class="apartment_collision" size="0.241826 0.021622 0.879405" pos="0.016051 0.257778 0" type="box"/>
              <geom name="geom_282" class="apartment_collision" size="0.058398 0.234783 0.281275" pos="0.199778 0 -0.524221" type="box"/>
              <geom name="geom_283" class="apartment_collision" size="0.196424 0.012277 0.318196" pos="-0.029351 0.223235 -0.561142" type="box"/>
              <geom name="geom_284" class="apartment_collision" size="0.196424 0.234783 0.058965" pos="-0.029351 0 -0.18398" type="box"/>
              <body gravcomp="1" name="fridge_drawer3" pos="-0.032657 0.00251899 -0.356176">
                <inertial pos="-0.0158874 -1.88399e-06 -0.016701" quat="0.515734 0.515717 -0.483776 0.483751" mass="40.7922" diaginertia="0.982233 0.67038 0.490644"/>
                <joint name="fridge_drawer3_joint" pos="0 0 0" axis="-1 0 0" type="slide" limited="true" range="0 0.3" actuatorfrclimited="false"/>
                <geom name="geom_285" class="apartment_visual" pos="-0.0171035 -1.80641e-06 -0.017107" quat="0.51742 0.517397 -0.481979 0.481947" type="mesh" material="SM_Fridge_Drawer_03" mesh="SM_Fridge_Drawer_03"/>
                <geom name="geom_286" class="apartment_collision" size="0.001 0.204478 0.05887" pos="-0.165482 0 -0.037113" type="box"/>
                <geom name="geom_287" class="apartment_collision" size="0.161445 0.00732 0.095915" pos="-0.004962 0.197083 0" type="box"/>
                <geom name="geom_288" class="apartment_collision" size="0.001555 0.204478 0.095915" pos="0.154928 0 0" type="box"/>
                <geom name="geom_289" class="apartment_collision" size="0.161445 0.00732 0.095915" pos="-0.004962 -0.197083 0" type="box"/>
                <geom name="geom_290" class="apartment_collision" size="0.161445 0.204478 0.000911" pos="-0.004962 0 -0.095072" type="box"/>
                <geom name="geom_291" class="apartment_collision" size="0.001 0.204478 0.012462" pos="-0.165482 0 0.083453" type="box"/>
              </body>
              <body gravcomp="1" name="fridge_shelf2" pos="-0.00102744 0.00204316 0.411236">
                <inertial pos="-0.0228107 -3.15254e-09 0.000275442" quat="0.499951 0.499951 -0.500049 0.500049" mass="2.10621" diaginertia="0.0522774 0.0384441 0.0138558"/>
                <geom name="geom_292" class="apartment_visual" pos="-0.049419 8.95497e-05 0.000606534" quat="0.49909 0.499327 -0.500667 0.500913" type="mesh" material="SM_Fridge_Shelf" mesh="SM_Fridge_Shelf"/>
              </body>
              <body gravcomp="1" name="fridge_drawer2" pos="-0.0154834 -0.00198811 -0.0496125">
                <inertial pos="-0.00961257 8.39292e-09 -0.00978441" quat="0.50173 0.50173 -0.498263 0.498263" mass="37.1956" diaginertia="1.03815 0.703314 0.426994"/>
                <joint name="fridge_drawer2_joint" pos="0 0 0" axis="-1 0 0" type="slide" limited="true" range="0 0.3" actuatorfrclimited="false"/>
                <geom name="geom_293" class="apartment_visual" pos="-0.0109552 1.92985e-08 -0.0097261" quat="0.502047 0.502047 -0.497944 0.497944" type="mesh" material="SM_Fridge_Drawer_02" mesh="SM_Fridge_Drawer_02"/>
                <geom name="geom_294" class="apartment_collision" size="0.002123 0.227117 0.068941" pos="0.16468 0 0" type="box"/>
                <geom name="geom_295" class="apartment_collision" size="0.0025 0.227117 0.011801" pos="-0.169309 0 0.057007" type="box"/>
                <geom name="geom_296" class="apartment_collision" size="0.001448 0.227117 0.032111" pos="-0.169309 0 -0.036775" type="box"/>
                <geom name="geom_297" class="apartment_collision" size="0.171761 0.00983 0.068941" pos="0 -0.217307 0" type="box"/>
                <geom name="geom_298" class="apartment_collision" size="0.171761 0.227117 0.001372" pos="0 0 -0.066161" type="box"/>
                <geom name="geom_299" class="apartment_collision" size="0.171761 0.00983 0.068941" pos="0 0.217307 0" type="box"/>
              </body>
              <body gravcomp="1" name="fridge_drawer5" pos="-0.0648077 0 -0.712787">
                <inertial pos="-0.0147473 -5.12698e-07 -0.0117161" quat="0.508635 0.508636 -0.491212 0.491214" mass="30.097" diaginertia="0.578778 0.507071 0.206707"/>
                <joint name="fridge_drawer5_joint" pos="0 0 0" axis="-1 0 0" type="slide" limited="true" range="0 0.3" actuatorfrclimited="false"/>
                <geom name="geom_300" class="apartment_visual" pos="-0.0167458 -5.09955e-07 -0.0117538" quat="0.512141 0.512143 -0.487555 0.487556" type="mesh" material="SM_Fridge_Drawer_05" mesh="SM_Fridge_Drawer_05"/>
              </body>
              <body gravcomp="1" name="fridge_shelf1" pos="-0.00102744 0.00204316 0.545451">
                <inertial pos="-0.0228107 -3.15254e-09 0.000275442" quat="0.499951 0.499951 -0.500049 0.500049" mass="2.10621" diaginertia="0.0522774 0.0384441 0.0138558"/>
                <geom name="geom_301" class="apartment_visual" pos="-0.049419 8.95497e-05 0.000606534" quat="0.49909 0.499327 -0.500667 0.500913" type="mesh" mesh="SM_Fridge_Shelf"/>
              </body>
              <body gravcomp="1" name="fridge_drawer1" pos="-0.012 0.00223595 0.110257">
                <inertial pos="-0.0095308 8.28997e-09 -0.0118601" quat="0.502682 0.502682 -0.497304 0.497304" mass="44.0781" diaginertia="1.22751 0.851636 0.533747"/>
                <joint name="fridge_drawer1_joint" pos="0 0 0" axis="-1 0 0" type="slide" limited="true" range="0 0.3" actuatorfrclimited="false"/>
                <geom name="geom_302" class="apartment_visual" pos="-0.0107914 1.92597e-08 -0.0119101" quat="0.503197 0.503197 -0.496783 0.496783" type="mesh" material="SM_Fridge_Drawer_01" mesh="SM_Fridge_Drawer_01"/>
                <geom name="geom_303" class="apartment_collision" size="0.171761 0.227117 0.001372" pos="0 0 -0.080999" type="box"/>
                <geom name="geom_304" class="apartment_collision" size="0.171761 0.00983 0.082076" pos="0 -0.217307 0" type="box"/>
                <geom name="geom_305" class="apartment_collision" size="0.002123 0.227117 0.082076" pos="0.16468 0 0" type="box"/>
                <geom name="geom_306" class="apartment_collision" size="0.171761 0.00983 0.082076" pos="0 0.217307 0" type="box"/>
                <geom name="geom_307" class="apartment_collision" size="0.001448 0.227117 0.047864" pos="-0.169309 0 -0.034598" type="box"/>
                <geom name="geom_308" class="apartment_collision" size="0.0025 0.227117 0.011921" pos="-0.169309 0 0.070506" type="box"/>
              </body>
              <body gravcomp="1" name="fridge_drawer4" pos="-0.0288522 0.00508168 -0.532998">
                <inertial pos="-0.0169733 -2.45802e-06 -0.0140746" quat="0.51386 0.513837 -0.485772 0.485743" mass="31.6556" diaginertia="0.762936 0.493252 0.354195"/>
                <joint name="fridge_drawer4_joint" pos="0 0 0" axis="-1 0 0" type="slide" limited="true" range="0 0.3" actuatorfrclimited="false"/>
                <geom name="geom_309" class="apartment_visual" pos="-0.0183517 -2.35018e-06 -0.0143476" quat="0.515258 0.515225 -0.484299 0.484259" type="mesh" material="SM_Fridge_Drawer_04" mesh="SM_Fridge_Drawer_04"/>
                <geom name="geom_310" class="apartment_collision" size="0.166408 0.008 0.075917" pos="0 -0.196311 0" type="box"/>
                <geom name="geom_311" class="apartment_collision" size="0.166408 0.204478 0.001" pos="0 0 -0.074992" type="box"/>
                <geom name="geom_312" class="apartment_collision" size="0.001 0.204478 0.075917" pos="0.155483 0 0" type="box"/>
                <geom name="geom_313" class="apartment_collision" size="0.001 0.204478 0.04" pos="-0.165482 0 -0.035978" type="box"/>
                <geom name="geom_314" class="apartment_collision" size="0.001 0.204478 0.012462" pos="-0.165482 0 0.063456" type="box"/>
                <geom name="geom_315" class="apartment_collision" size="0.166408 0.008 0.075917" pos="0 0.196311 0" type="box"/>
              </body>
            </body>
            <body gravcomp="1" name="fridge_door1" pos="-0.297259 0.299145 0.25674">
              <inertial pos="0.0250154 -0.290232 0.0635432" quat="0.999995 0.00166946 -0.0027064 -0.000228724" mass="87.8838" diaginertia="12.1081 9.65011 2.50191"/>
              <joint name="fridge_door1_joint" pos="0 0 0" axis="0 0 -1" limited="true" range="0 1.5708" actuatorfrclimited="false"/>
              <geom name="geom_316" class="apartment_visual" pos="0.0269719 -0.287261 0.0594776" quat="0.999996 0.00220778 -0.00173997 7.69889e-05" type="mesh" material="SM_Fridge_Door_01" mesh="SM_Fridge_Door_01"/>
              <geom name="geom_317" class="apartment_collision" size="0.009277 0.298246 0.668339" pos="0.006948 -0.297325 0.139709" type="box"/>
              <body gravcomp="1" name="fridge_door_tray1" pos="0.103791 -0.297261 -0.0156525">
                <inertial pos="-0.000140626 -0.00094467 -0.00722341" quat="0.513922 0.511533 -0.486993 0.486884" mass="7.60697" diaginertia="0.127314 0.123662 0.0130837"/>
                <geom name="geom_318" class="apartment_collision" size="0.05471 0.001 0.047787" pos="0 -0.209978 0" type="box"/>
                <geom name="geom_319" class="apartment_collision" size="0.05471 0.210927 0.001" pos="0 0 -0.047166" type="box"/>
                <geom name="geom_320" class="apartment_collision" size="0.001 0.210927 0.047787" pos="0.054273 0 0" type="box"/>
                <geom name="geom_321" class="apartment_collision" size="0.001 0.210927 0.047787" pos="-0.054273 0 0" type="box"/>
                <geom name="geom_322" class="apartment_collision" size="0.05471 0.001 0.047787" pos="0 0.209978 0" type="box"/>
                <geom name="geom_323" class="apartment_visual" pos="-0.000146205 -0.000982955 -0.00691971" quat="0.515051 0.512558 -0.485865 0.485738" type="mesh" material="SM_Fridge_Door_Tray_01" mesh="SM_Fridge_Door_Tray_01"/>
              </body>
              <body gravcomp="1" name="fridge_door1_handle" pos="-0.027991 -0.465343 -0.3616" quat="0.707107 0.707107 0 0">
                <inertial pos="0.00608124 7.62691e-06 0.000219453" quat="0.707535 -0.0001654 -4.86875e-05 0.706679" mass="0.101418" diaginertia="0.000334346 0.000326533 1.03303e-05"/>
                <geom name="geom_324" class="apartment_visual" pos="0.00753596 3.13834e-07 -1.61273e-05" quat="0.707258 0.000144565 8.61629e-05 0.706956" type="mesh" mesh="SM_Kitchen_Handle"/>
                <geom name="geom_325" class="apartment_collision" size="0.01 0.0065 0.0065" pos="0.0164985 0 0.08" type="box"/>
                <geom name="geom_326" class="apartment_collision" size="0.0065 0.0065 0.086516" type="box"/>
                <geom name="geom_327" class="apartment_collision" size="0.01 0.0065 0.0065" pos="0.0164985 0 -0.08" type="box"/>
              </body>
              <body gravcomp="1" name="fridge_door_tray2" pos="0.101769 -0.298471 0.223872">
                <inertial pos="0.000378681 -5.22744e-06 -0.00505777" quat="0.499098 0.499098 -0.500905 0.500896" mass="4.128" diaginertia="0.0704551 0.0667114 0.00528892"/>
                <geom name="geom_328" class="apartment_visual" pos="0.000398594 -5.49061e-06 -0.00471193" quat="0.499056 0.499056 -0.500947 0.500938" type="mesh" material="SM_Fridge_Door_Tray_02" mesh="SM_Fridge_Door_Tray_02"/>
                <geom name="geom_329" class="apartment_collision" size="0.054994 0.001 0.026901" pos="0 -0.209978 0" type="box"/>
                <geom name="geom_330" class="apartment_collision" size="0.054994 0.210977 0.001" pos="0 0 -0.025903" type="box"/>
                <geom name="geom_331" class="apartment_collision" size="0.001 0.210977 0.026901" pos="0.054019 0 0" type="box"/>
                <geom name="geom_332" class="apartment_collision" size="0.054994 0.001 0.026901" pos="0 0.209978 0" type="box"/>
                <geom name="geom_333" class="apartment_collision" size="0.001 0.210977 0.026901" pos="-0.054019 0 0" type="box"/>
                <body gravcomp="1" name="fridge_egg_tray" pos="-0.00226576 0.0853089 0.00069855">
                  <inertial pos="0.0127439 6.80984e-06 0.00359793" quat="0.000638201 0.814171 -0.000452353 0.580625" mass="0.246655" diaginertia="0.000635897 0.000342927 0.000306836"/>
                  <geom name="geom_334" class="apartment_visual" pos="0.0127441 6.64115e-06 0.00359782" quat="0.000638201 0.814171 -0.000452353 0.580625" type="mesh" material="SM_Fridge_Egg_Tray" mesh="SM_Fridge_Egg_Tray"/>
                </body>
              </body>
            </body>
          </body>
          <body gravcomp="1" name="cabinet5" pos="0.274766 3.08412 0.494207" quat="0 0 0 1">
            <inertial pos="0.0496572 2.2528e-05 -0.0627537" quat="0.997441 0.00037226 0.0714948 -4.00552e-05" mass="400.802" diaginertia="34.5511 26.8623 22.9874"/>
            <geom name="geom_335" class="apartment_visual" pos="0.0499067 2.39341e-05 -0.0621769" quat="0.997432 0.000396897 0.0716159 -4.32788e-05" type="mesh" material="SM_Kitchen_05_Base" mesh="SM_Kitchen_05_Base"/>
            <body gravcomp="1" name="cabinet5_drawer3" pos="-0.0534509 -0.00075551 -0.1971">
              <inertial pos="-0.0220108 -6.431e-07 -0.0795975" quat="1.11116e-05 0.787047 -7.22533e-06 0.616893" mass="115.125" diaginertia="6.18025 3.83482 3.5993"/>
              <joint name="cabinet5_drawer3_joint" pos="0 0 0" axis="-1 0 0" type="slide" limited="true" range="0 0.45" actuatorfrclimited="false"/>
              <geom name="geom_336" class="apartment_visual" pos="-0.0192353 -5.28482e-07 -0.0790552" quat="1.61793e-05 0.7855 -1.10844e-05 0.618862" type="mesh" material="SM_Kitchen_05_Drawer_03" mesh="SM_Kitchen_05_Drawer_03"/>
              <geom name="geom_337" class="apartment_collision" size="0.008 0.298 0.2" pos="-0.234 0 0" type="box"/>
              <geom name="geom_338" class="apartment_collision" size="0.25 0.27 0.008" pos="0.025 0 -0.164" type="box"/>
              <geom name="geom_339" class="apartment_collision" size="0.25 0.008 0.08" pos="0.025 -0.27 -0.075" type="box"/>
              <geom name="geom_340" class="apartment_collision" size="0.25 0.008 0.08" pos="0.025 0.27 -0.075" type="box"/>
              <geom name="geom_341" class="apartment_collision" size="0.008 0.26 0.08" pos="0.26 0 -0.075" type="box"/>
              <body gravcomp="1" name="cabinet5_drawer3_handle" pos="-0.268882 0.00102875 0.15027" quat="0.707107 0.707107 0 0">
                <inertial pos="0.00608124 7.62691e-06 0.000219453" quat="0.707535 -0.0001654 -4.86875e-05 0.706679" mass="0.101418" diaginertia="0.000334346 0.000326533 1.03303e-05"/>
                <geom name="geom_342" class="apartment_visual" pos="0.00753596 3.13834e-07 -1.61273e-05" quat="0.707258 0.000144565 8.61629e-05 0.706956" type="mesh" mesh="SM_Kitchen_Handle"/>
                <geom name="geom_343" class="apartment_collision" size="0.01 0.0065 0.0065" pos="0.0164985 0 0.08" type="box"/>
                <geom name="geom_344" class="apartment_collision" size="0.0065 0.0065 0.086516" type="box"/>
                <geom name="geom_345" class="apartment_collision" size="0.01 0.0065 0.0065" pos="0.0164985 0 -0.08" type="box"/>
              </body>
            </body>
            <body gravcomp="1" name="cabinet5_drawer1" pos="-0.052627 -0.00100026 0.331778">
              <inertial pos="0.00115867 -2.90281e-07 -0.0214327" quat="0.507161 0.50717 -0.492726 0.492734" mass="57.6743" diaginertia="3.09476 1.71648 1.4527"/>
              <joint name="cabinet5_drawer1_joint" pos="0 0 0" axis="-1 0 0" type="slide" limited="true" range="0 0.45" actuatorfrclimited="false"/>
              <geom name="geom_346" class="apartment_visual" pos="0.00216003 -4.02312e-07 -0.0203236" quat="0.506956 0.506965 -0.492937 0.492945" type="mesh" material="SM_Kitchen_05_Drawer_01" mesh="SM_Kitchen_05_Drawer_01"/>
              <geom name="geom_347" class="apartment_collision" size="0.008 0.298 0.065" pos="-0.234 0 0" type="box"/>
              <geom name="geom_348" class="apartment_collision" size="0.25 0.27 0.008" pos="0.025 0 -0.045" type="box"/>
              <geom name="geom_349" class="apartment_collision" size="0.25 0.008 0.034" pos="0.025 -0.27 -0.005" type="box"/>
              <geom name="geom_350" class="apartment_collision" size="0.25 0.008 0.034" pos="0.025 0.27 -0.005" type="box"/>
              <geom name="geom_351" class="apartment_collision" size="0.008 0.26 0.034" pos="0.26 0 -0.005" type="box"/>
              <body gravcomp="1" name="cabinet5_drawer1_handle" pos="-0.269809 0.00142363 0.0167695" quat="0.707107 0.707107 0 0">
                <inertial pos="0.00608124 7.62691e-06 0.000219453" quat="0.707535 -0.0001654 -4.86875e-05 0.706679" mass="0.101418" diaginertia="0.000334346 0.000326533 1.03303e-05"/>
                <geom name="geom_352" class="apartment_visual" pos="0.00753596 3.13834e-07 -1.61273e-05" quat="0.707258 0.000144565 8.61629e-05 0.706956" type="mesh" mesh="SM_Kitchen_Handle"/>
                <geom name="geom_353" class="apartment_collision" size="0.01 0.0065 0.0065" pos="0.0164985 0 0.08" type="box"/>
                <geom name="geom_354" class="apartment_collision" size="0.0065 0.0065 0.086516" type="box"/>
                <geom name="geom_355" class="apartment_collision" size="0.01 0.0065 0.0065" pos="0.0164985 0 -0.08" type="box"/>
              </body>
            </body>
            <body gravcomp="1" name="cabinet5_drawer2" pos="-0.0530376 -0.00079152 0.1345">
              <inertial pos="-0.00180101 -6.37148e-07 -0.0503348" quat="0.52345 0.523541 -0.475304 0.475386" mass="98.0957" diaginertia="5.2413 2.9346 2.89318"/>
              <joint name="cabinet5_drawer2_joint" pos="0 0 0" axis="-1 0 0" type="slide" limited="true" range="0 0.45" actuatorfrclimited="false"/>
              <geom name="geom_356" class="apartment_visual" pos="0.000185324 -6.37643e-07 -0.0491402" quat="0.523037 0.523083 -0.475802 0.475845" type="mesh" material="SM_Kitchen_05_Drawer_02" mesh="SM_Kitchen_05_Drawer_02"/>
              <geom name="geom_357" class="apartment_collision" size="0.008 0.298 0.13" pos="-0.234 0 0" type="box"/>
              <geom name="geom_358" class="apartment_collision" size="0.25 0.27 0.008" pos="0.025 0 -0.12" type="box"/>
              <geom name="geom_359" class="apartment_collision" size="0.25 0.008 0.08" pos="0.025 -0.27 -0.03" type="box"/>
              <geom name="geom_360" class="apartment_collision" size="0.25 0.008 0.08" pos="0.025 0.27 -0.03" type="box"/>
              <geom name="geom_361" class="apartment_collision" size="0.008 0.26 0.082" pos="0.26 0 -0.03" type="box"/>
              <body gravcomp="1" name="cabinet5_drawer2_handle" pos="-0.270711 0.00106413 0.0850084" quat="0.707107 0.707107 0 0">
                <inertial pos="0.00608124 7.62691e-06 0.000219453" quat="0.707535 -0.0001654 -4.86875e-05 0.706679" mass="0.101418" diaginertia="0.000334346 0.000326533 1.03303e-05"/>
                <geom name="geom_362" class="apartment_visual" pos="0.00753596 3.13834e-07 -1.61273e-05" quat="0.707258 0.000144565 8.61629e-05 0.706956" type="mesh" mesh="SM_Kitchen_Handle"/>
                <geom name="geom_363" class="apartment_collision" size="0.01 0.0065 0.0065" pos="0.0164985 0 0.08" type="box"/>
                <geom name="geom_364" class="apartment_collision" size="0.0065 0.0065 0.086516" type="box"/>
                <geom name="geom_365" class="apartment_collision" size="0.01 0.0065 0.0065" pos="0.0164985 0 -0.08" type="box"/>
              </body>
            </body>
          </body>
          <body gravcomp="1" name="cabinet2" pos="0.279909 1.97705 1.16239" quat="0 0 0 1">
            <inertial pos="0.0200629 0.000499064 0.14528" quat="0.720766 -0.00273247 -0.00290308 0.693167" mass="870.224" diaginertia="361.921 359.527 29.0664"/>
            <geom name="geom_366" class="apartment_visual" pos="0.0191364 0.000532152 0.15058" quat="0.721025 -0.00266914 -0.00284997 0.692898" type="mesh" material="SM_Kitchen_02_Base" mesh="SM_Kitchen_02_Base"/>
            <geom name="geom_367" class="apartment_collision" size="0.004 0.183882 1.04784" pos="0.267372 0 0" type="box"/>
            <geom name="geom_368" class="apartment_collision" size="0.277359 0.008 1.06384" pos="0.005897 -0.191979 0" type="box"/>
            <geom name="geom_369" class="apartment_collision" size="0.007187 0.183882 0.031996" pos="-0.26039 0 1.01584" type="box"/>
            <body gravcomp="1" name="cabinet2_drawer1" pos="-0.00464775 0.00134538 0.580462">
              <inertial pos="-0.00249393 0.000205988 -0.0148373" quat="-0.000287128 0.708463 0.000286027 0.705748" mass="36.9805" diaginertia="1.27627 0.845487 0.469471"/>
              <joint name="cabinet2_drawer1_joint" pos="0 0 0" axis="-1 0 0" type="slide" limited="true" range="0 0.45" actuatorfrclimited="false"/>
              <geom name="geom_370" class="apartment_visual" pos="-0.00192339 0.000251478 -0.0130483" quat="-0.000345536 0.70884 0.00037078 0.705369" type="mesh" material="SM_Kitchen_02_Drawer_01" mesh="SM_Kitchen_02_Drawer_01"/>
              <geom name="geom_371" class="apartment_collision" size="0.247489 0.008 0.050495" pos="-0.003984 -0.170578 0" type="box"/>
              <geom name="geom_372" class="apartment_collision" size="0.008064 0.180981 0.050495" pos="0.235441 0 0" type="box"/>
              <geom name="geom_373" class="apartment_collision" size="0.247489 0.008 0.050495" pos="-0.003984 0.170578 0" type="box"/>
              <geom name="geom_374" class="apartment_collision" size="0.247489 0.180981 0.010749" pos="-0.003984 0 -0.039746" type="box"/>
              <geom name="geom_375" class="apartment_collision" size="0.0085 0.180981 0.050495" pos="-0.242975 0 0" type="box"/>
            </body>
            <body gravcomp="1" name="cabinet2_drawer5" pos="-0.00464775 0.00134538 -0.518096">
              <inertial pos="0.00614209 0.000214311 -0.0299913" quat="-0.000261606 0.701401 0.00027151 0.712767" mass="53.4013" diaginertia="1.87121 1.35339 0.729655"/>
              <joint name="cabinet2_drawer5_joint" pos="0 0 0" axis="-1 0 0" type="slide" limited="true" range="0 0.45" actuatorfrclimited="false"/>
              <geom name="geom_376" class="apartment_visual" pos="0.00752082 0.000290022 -0.0273169" quat="-0.000517221 0.701955 0.000506063 0.712221" type="mesh" mesh="SM_Kitchen_02_Drawer_02"/>
              <geom name="geom_377" class="apartment_collision" size="0.008393 0.032441 0.09099" pos="-0.242869 0.148428 0" type="box"/>
              <geom name="geom_378" class="apartment_collision" size="0.008393 0.032441 0.09099" pos="-0.242869 -0.148428 0" type="box"/>
              <geom name="geom_379" class="apartment_collision" size="0.247489 0.180981 0.010749" pos="-0.003984 0 -0.080242" type="box"/>
              <geom name="geom_380" class="apartment_collision" size="0.247489 0.008 0.011649" pos="-0.003984 0.170578 0.075342" type="box"/>
              <geom name="geom_381" class="apartment_collision" size="0.247489 0.008 0.011649" pos="-0.003984 -0.170578 0.075342" type="box"/>
              <geom name="geom_382" class="apartment_collision" size="0.247489 0.008 0.043553" pos="-0.003984 0.170578 -0.043743" type="box"/>
              <geom name="geom_383" class="apartment_collision" size="0.247489 0.008 0.043553" pos="-0.003984 -0.170578 -0.043743" type="box"/>
              <geom name="geom_384" class="apartment_collision" size="0.006898 0.180981 0.010149" pos="-0.242374 0 0.060843" type="box"/>
              <geom name="geom_385" class="apartment_collision" size="0.006898 0.180981 0.049" pos="-0.242374 0 -0.042" type="box"/>
              <geom name="geom_386" class="apartment_collision" size="0.008064 0.180981 0.090879" pos="0.235441 0 0" type="box"/>
            </body>
            <body gravcomp="1" name="cabinet2_drawer2" pos="-0.00464775 -0.00134538 0.422749">
              <inertial pos="0.00614209 0.000214311 -0.0299913" quat="-0.000261606 0.701401 0.00027151 0.712767" mass="53.4013" diaginertia="1.87121 1.35339 0.729655"/>
              <joint name="cabinet2_drawer2_joint" pos="0 0 0" axis="-1 0 0" type="slide" limited="true" range="0 0.45" actuatorfrclimited="false"/>
              <geom name="geom_387" class="apartment_visual" pos="0.00752082 0.000290022 -0.0273169" quat="-0.000517221 0.701955 0.000506063 0.712221" type="mesh" material="SM_Kitchen_02_Drawer_02" mesh="SM_Kitchen_02_Drawer_02"/>
              <geom name="geom_388" class="apartment_collision" size="0.247489 0.008 0.043553" pos="-0.003984 0.170578 -0.043743" type="box"/>
              <geom name="geom_389" class="apartment_collision" size="0.008064 0.180981 0.090879" pos="0.235441 0 0" type="box"/>
              <geom name="geom_390" class="apartment_collision" size="0.006898 0.180981 0.049" pos="-0.242374 0 -0.042" type="box"/>
              <geom name="geom_391" class="apartment_collision" size="0.247489 0.008 0.011649" pos="-0.003984 0.170578 0.075342" type="box"/>
              <geom name="geom_392" class="apartment_collision" size="0.006898 0.180981 0.010149" pos="-0.242374 0 0.060843" type="box"/>
              <geom name="geom_393" class="apartment_collision" size="0.247489 0.008 0.011649" pos="-0.003984 -0.170578 0.075342" type="box"/>
              <geom name="geom_394" class="apartment_collision" size="0.247489 0.180981 0.010749" pos="-0.003984 0 -0.080242" type="box"/>
              <geom name="geom_395" class="apartment_collision" size="0.008393 0.032441 0.09099" pos="-0.242869 0.148428 0" type="box"/>
              <geom name="geom_396" class="apartment_collision" size="0.247489 0.008 0.043553" pos="-0.003984 -0.170578 -0.043743" type="box"/>
              <geom name="geom_397" class="apartment_collision" size="0.008393 0.032441 0.09099" pos="-0.242869 -0.148428 0" type="box"/>
            </body>
            <body gravcomp="1" name="cabinet2_drawer6" pos="-0.00464775 0.00134538 -0.955192">
              <inertial pos="0.00614209 0.000214311 -0.0299913" quat="-0.000261606 0.701401 0.00027151 0.712767" mass="53.4013" diaginertia="1.87121 1.35339 0.729655"/>
              <joint name="cabinet2_drawer6_joint" pos="0 0 0" axis="-1 0 0" type="slide" limited="true" range="0 0.45" actuatorfrclimited="false"/>
              <geom name="geom_398" class="apartment_visual" pos="0.00752082 0.000290022 -0.0273169" quat="-0.000517221 0.701955 0.000506063 0.712221" type="mesh" mesh="SM_Kitchen_02_Drawer_02"/>
              <geom name="geom_399" class="apartment_collision" size="0.008393 0.032441 0.09099" pos="-0.242869 0.148428 0" type="box"/>
              <geom name="geom_400" class="apartment_collision" size="0.247489 0.008 0.011649" pos="-0.003984 -0.170578 0.075342" type="box"/>
              <geom name="geom_401" class="apartment_collision" size="0.247489 0.180981 0.010749" pos="-0.003984 0 -0.080242" type="box"/>
              <geom name="geom_402" class="apartment_collision" size="0.008064 0.180981 0.090879" pos="0.235441 0 0" type="box"/>
              <geom name="geom_403" class="apartment_collision" size="0.006898 0.180981 0.010149" pos="-0.242374 0 0.060843" type="box"/>
              <geom name="geom_404" class="apartment_collision" size="0.006898 0.180981 0.049" pos="-0.242374 0 -0.042" type="box"/>
              <geom name="geom_405" class="apartment_collision" size="0.247489 0.008 0.011649" pos="-0.003984 0.170578 0.075342" type="box"/>
              <geom name="geom_406" class="apartment_collision" size="0.008393 0.032441 0.09099" pos="-0.242869 -0.148428 0" type="box"/>
              <geom name="geom_407" class="apartment_collision" size="0.247489 0.008 0.043553" pos="-0.003984 -0.170578 -0.043743" type="box"/>
              <geom name="geom_408" class="apartment_collision" size="0.247489 0.008 0.043553" pos="-0.003984 0.170578 -0.043743" type="box"/>
            </body>
            <body gravcomp="1" name="cabinet2_door" pos="-0.284321 0.18657 0.00105865">
              <inertial pos="-0.00050394 -0.181191 0.00372915" quat="0.999999 -0.000681578 2.4303e-05 -0.000744334" mass="33.0152" diaginertia="12.9084 12.4712 0.439256"/>
              <joint name="cabinet2_door_joint" pos="0 0 0" axis="0 0 -1" limited="true" range="0 1.5708" actuatorfrclimited="false"/>
              <geom name="geom_409" class="apartment_visual" pos="-0.00036349 -0.177535 0.00723595" quat="0.999998 -0.00128026 4.48458e-05 -0.00139256" type="mesh" material="SM_Kitchen_02_Door" mesh="SM_Kitchen_02_Door"/>
              <geom name="geom_410" class="apartment_collision" size="0.0095 0.19 1.06138" pos="-0.000653 -0.185074 0" type="box"/>
              <body gravcomp="1" name="cabinet2_door_handle" pos="-0.0218499 -0.25886 -0.105189" quat="0.707107 0.707107 0 0">
                <inertial pos="0.00608124 7.62691e-06 0.000219453" quat="0.707535 -0.0001654 -4.86875e-05 0.706679" mass="0.101418" diaginertia="0.000334346 0.000326533 1.03303e-05"/>
                <geom name="geom_411" class="apartment_visual" pos="0.00753596 3.13834e-07 -1.61273e-05" quat="0.707258 0.000144565 8.61629e-05 0.706956" type="mesh" mesh="SM_Kitchen_Handle"/>
                <geom name="geom_412" class="apartment_collision" size="0.01 0.0065 0.0065" pos="0.0164985 0 0.08" type="box"/>
                <geom name="geom_413" class="apartment_collision" size="0.0065 0.0065 0.086516" type="box"/>
                <geom name="geom_414" class="apartment_collision" size="0.01 0.0065 0.0065" pos="0.0164985 0 -0.08" type="box"/>
              </body>
            </body>
            <body gravcomp="1" name="cabinet2_drawer3" pos="-0.00464775 -0.00134538 0.142897">
              <inertial pos="0.00614209 0.000214311 -0.0299913" quat="-0.000261606 0.701401 0.00027151 0.712767" mass="53.4013" diaginertia="1.87121 1.35339 0.729655"/>
              <joint name="cabinet2_drawer3_joint" pos="0 0 0" axis="-1 0 0" type="slide" limited="true" range="0 0.45" actuatorfrclimited="false"/>
              <geom name="geom_415" class="apartment_visual" pos="0.00752082 0.000290022 -0.0273169" quat="-0.000517221 0.701955 0.000506063 0.712221" type="mesh" mesh="SM_Kitchen_02_Drawer_02"/>
              <geom name="geom_416" class="apartment_collision" size="0.247489 0.008 0.043553" pos="-0.003984 -0.170578 -0.043743" type="box"/>
              <geom name="geom_417" class="apartment_collision" size="0.006898 0.180981 0.049" pos="-0.242374 0 -0.042" type="box"/>
              <geom name="geom_418" class="apartment_collision" size="0.247489 0.008 0.011649" pos="-0.003984 0.170578 0.075342" type="box"/>
              <geom name="geom_419" class="apartment_collision" size="0.008064 0.180981 0.090879" pos="0.235441 0 0" type="box"/>
              <geom name="geom_420" class="apartment_collision" size="0.006898 0.180981 0.010149" pos="-0.242374 0 0.060843" type="box"/>
              <geom name="geom_421" class="apartment_collision" size="0.247489 0.008 0.043553" pos="-0.003984 0.170578 -0.043743" type="box"/>
              <geom name="geom_422" class="apartment_collision" size="0.247489 0.180981 0.010749" pos="-0.003984 0 -0.080242" type="box"/>
              <geom name="geom_423" class="apartment_collision" size="0.247489 0.008 0.011649" pos="-0.003984 -0.170578 0.075342" type="box"/>
              <geom name="geom_424" class="apartment_collision" size="0.008393 0.032441 0.09099" pos="-0.242869 -0.148428 0" type="box"/>
              <geom name="geom_425" class="apartment_collision" size="0.008393 0.032441 0.09099" pos="-0.242869 0.148428 0" type="box"/>
            </body>
            <body gravcomp="1" name="cabinet2_shelf" pos="-0.00337784 0.00043732 0.790361">
              <inertial pos="5.91191e-06 -3.56633e-08 0.00485682" quat="-2.12085e-06 0.707108 2.12085e-06 0.707106" mass="5.38868" diaginertia="0.166355 0.105166 0.0613989"/>
              <geom name="geom_426" class="apartment_visual" pos="1.16736e-05 -2.72391e-07 0.00476473" quat="-4.21306e-06 0.707109 4.21303e-06 0.707105" type="mesh" material="SM_Kitchen_02_Shelf" mesh="SM_Kitchen_02_Shelf"/>
            </body>
            <body gravcomp="1" name="cabinet2_drawer4" pos="-0.00464775 0.00134538 -0.242437">
              <inertial pos="0.00614209 0.000214311 -0.0299913" quat="-0.000261606 0.701401 0.00027151 0.712767" mass="53.4013" diaginertia="1.87121 1.35339 0.729655"/>
              <joint name="cabinet2_drawer4_joint" pos="0 0 0" axis="-1 0 0" type="slide" limited="true" range="0 0.45" actuatorfrclimited="false"/>
              <geom name="geom_427" class="apartment_visual" pos="0.00752082 0.000290022 -0.0273169" quat="-0.000517221 0.701955 0.000506063 0.712221" type="mesh" mesh="SM_Kitchen_02_Drawer_02"/>
              <geom name="geom_428" class="apartment_collision" size="0.247489 0.008 0.011649" pos="-0.003984 0.170578 0.075342" type="box"/>
              <geom name="geom_429" class="apartment_collision" size="0.006898 0.180981 0.049" pos="-0.242374 0 -0.042" type="box"/>
              <geom name="geom_430" class="apartment_collision" size="0.008393 0.032441 0.09099" pos="-0.242869 -0.148428 0" type="box"/>
              <geom name="geom_431" class="apartment_collision" size="0.006898 0.180981 0.010149" pos="-0.242374 0 0.060843" type="box"/>
              <geom name="geom_432" class="apartment_collision" size="0.008064 0.180981 0.090879" pos="0.235441 0 0" type="box"/>
              <geom name="geom_433" class="apartment_collision" size="0.247489 0.008 0.011649" pos="-0.003984 -0.170578 0.075342" type="box"/>
              <geom name="geom_434" class="apartment_collision" size="0.008393 0.032441 0.09099" pos="-0.242869 0.148428 0" type="box"/>
              <geom name="geom_435" class="apartment_collision" size="0.247489 0.180981 0.010749" pos="-0.003984 0 -0.080242" type="box"/>
              <geom name="geom_436" class="apartment_collision" size="0.247489 0.008 0.043553" pos="-0.003984 0.170578 -0.043743" type="box"/>
              <geom name="geom_437" class="apartment_collision" size="0.247489 0.008 0.043553" pos="-0.003984 -0.170578 -0.043743" type="box"/>
            </body>
          </body>
        </body>
      </body>
    </body>
  </worldbody>
</mujoco>
